Workbook

Sheet PKD SALES
D2: PEDOMAN MUTU
D3: PT.TIKI JALUR NUGRAHA EKAKURIR
D4: PROGRAM KERJA DEPARTEMEN / ANALIS
D5: Nomor : | F5: Revisi : 00 | K5: Departemen/Analis. | L5: :
D6: Tanggal Terbit : | F6: Halaman : 01/01 | K6: Divisi | L6: :
B8: NO. | C8: KEBIJAKAN MUTU | D8: SASARAN MUTU | F8: PROGRAM KERJA | H8: TARGET PENCAPAIAN Wajib Terukur - (Jumlah | Persentase | Waktu) | J8: OUTCOME | K8: PIC | L8: BOBOT (%) | M8: WAKTU
M9: Q1 | P9: Q2 | S9: Q3 | V9: Q4
M10: 1 | N10: 2 | O10: 3 | P10: 4 | Q10: 5 | R10: 6 | S10: 7 | T10: 8 | U10: 9 | V10: 10 | W10: 11 | X10: 12
B12: 1 | C12: DRIVEN GREAT BUSINESS OUTCOMES | D12: 1.1. | E12: Build Business Outcomes - Financial: •Increased Profitability •Revenue Growth •Improved Profit Margins | F12: 1.1.1. | G12: Efisiensi pricing strategy: Publish price, BA, BT & BP | H12: 1.1.1.1 | I12: 100 % Tarif Rate dilakukan review (competitiveness, profit margin, routing cost evaluation) | J12: Tersedianya tarif yang kompetitif sehingga menjadi keunggulan dalam customer memilih layanan JNE | K12: REGIONAL, KACAB, SALES, OPS, ACC FIN | L12: 0.02
H13: 1.1.1.2 | I13: Supporting System Monitoring (P&L by Customer) | K13: REG SALES, IT, ACC FIN | L13: 0.02
F14: 1.1.2. | G14: Kemampuan menganalisa profitabilitas HPP dari origin sales tersebut terutama untuk destinasi intraregional & intracity (Terutama yang menggunakan moda darat)* | H14: 1.1.2.1 | I14: 100 % review profitability shipment destinasi intra regional dan intracity | K14: KACAB, SALES, OPS, ACC FIN | L14: 0.02
H15: 1.1.2.2 | I15: peningkatan kiriman Intraregional dan intracity sebesar 10% | K15: KACAB, SALES | L15: 0.03
F16: 1.1.3. | G16: Upselling and Crosselling for profitable volume | H16: 1.1.3.1 | I16: Peningkatan penjualan top 10 profitable destinasi | K16: REGIONAL, KACAB, SALES | L16: 0.03
D17: 1.2. | E17: Build Business Outcomes - Customers: •Higher Customers Satisfactions •Increased Retentions •Higher Brand Loyalty | F17: 1.2.1. | G17: Membuat program untuk mendapatkan insight dari selective customer secara periodic untuk memperbaiki service JNE dan melakukan matchmaking yang dapat meningkatkan kepuasan customer** | H17: 1.2.1.1 | I17: monthly CCC review report for pareto customer/top 10 customer | J17: Memahami bisnis proses pelanggan dengan mengetahui kebutuhan customer untuk mendapatkan peluang upselling & crosselling | K17: KACAB, SALES | L17: 0.02
F18: 1.2.2. | G18: Memberikan Business Review dan insight (Pricing & service) terhadap strategic customer dan top customer secara periodic | H18: 1.2.2.1 | I18: 12 top customer collaboration | K18: KACAB, SALES | L18: 0.02
F19: 1.2.3. | G19: Memberikan Business Review dan insight (Pricing & service) terhadap strategic customer dan top customer secara periodic | H19: 1.2.3.1 | I19: Top 10 JLC Customer maintain by RCC | K19: KACAB, SALES | L19: 0.03
H20: 1.2.3.2 | I20: Peningkatan revenue JLC Member sebesar 10% | J20: Memahami bisnis proses pelanggan dengan mengetahui kebutuhan customer untuk mendapatkan peluang upselling & crosselling | K20: KACAB, SALES | L20: 0.02
D21: 1.3 | E21: Build Business Outcomes - Strategics: New Markets, Becoming Market Leader, Successful Innovation | F21: 1.3.1 | G21: Fokus terhadap industry government: -Mendapatkan peluang tender baik di sirup, e-catalog maupun penunjukan langsung yang berkaitan dengan administrasi -Mencari Network/Chanel di lembaga pemerintah dan BUMN -Memberikan edukasi kepada government yang berkaitan dengan proses distribusi yang efektif dan efisien** | H21: 1.3.1.1 | I21: 3 promo program for government segment customer | K21: KACAB, SALES | L21: 0.02
H22: 1.3.1.2 | I22: Peningkatan revenue Government sebesar 27% | K22: KACAB, SALES | L22: 0.02
F23: 1.3.2 | G23: Dapat menjual kiriman koper traveler, logistical support for MICE, FM-MM-LM, kubikasi, LCL, FTL, FCL, International** | H23: 1.3.2.1 | I23: LCL, FTL, FCL 50 trx/month / Target Growth 15% from Last Year | K23: KACAB, SALES | L23: 0.03
H24: 1.3.2.2 | I24: Roket/AM PM 50 trx/month / Target Growth 15% from Last Year | K24: KACAB, SALES | L24: 0.03
F25: 1.3.3 | G25: Special Cargo (tanaman, frozen, binatang hidup, DG, komoditi)** | H25: 1.3.3.1 | I25: Special Cargo Growth 15% from Last Year | K25: KACAB, SALES | L25: 0.03
D26: 1.4 | E26: Build Business Outcomes - Improving Customer Satisfactions: •Increasing Business & Customers Retentions •Build Solutions (Efficient, Effective, Productivity) | F26: 1.4.1 | G26: Meningkatkan kompetensi tim sales melalui workshop solusi bisnis dengan tim yang sama dari pelanggan strategic (Contoh: Banking, project TV) | H26: 1.4.1.1 | I26: 4 sesi/year | J26: Melaksanakan pelatihan & pengembangan keterampilan, pengetahuan, penjualan secara konsisten dan terukur | K26: REGIONAL, KACAB, SALES | L26: 0.02
F27: 1.4.2 | G27: Optimalisasi feedback dari customer dan menyampaikan ke direktorat terkait | H27: 1.4.2.1 | I27: monthly report voice of customer | K27: KACAB, SALES | L27: 0.02
F28: 1.4.3 | G28: Monthly report update market/kompetitor (tarif, promo,service quality) | H28: 1.4.3.1 | I28: monthly report update market & kompetitor | K28: KACAB, SALES | L28: 0.02
D29: 1.5 | E29: Build Business Outcomes - Build Trust, Trust is Paramount: •Deliver Promise •Clients Successful •Value the Business & Go Extra Mile | F29: 1.5.1 | G29: Memonitor secara berkala WI yang ada berjalan sesuai dengan isinya dan kondisi di lapangan | H29: 1.5.1.1 | I29: 100% cust WI on checked | K29: KACAB, SALES | L29: 0.02
D30: 1.6 | E30: Effective Selling: -Value based selling -Building relationship -Improve performance -Customers engagement -Networking value -Profiling customer | F30: 1.6.1 | G30: Memahami permintaan customer untuk memberikan pelayanan diluar servis standar (Fulfillment, ads subsidy, cargo, sponsorship, export import, dsb) | H30: 1.6.1.1 | I30: 1 cust fullfillment | K30: KACAB, SALES | L30: 0.02
H31: 1.6.1.2 | I31: International 20 trx/month / Target Growth 15% From Last Year | K31: KACAB, SALES | L31: 0.03
F32: 1.6.2 | G32: Mendapatkan leads baru dari network existing customer | H32: 1.6.2.1 | I32: 3 New Cust/Sales (Monthly) | K32: KACAB, SALES | L32: 0.02
D33: 1.7 | E33: Sales Performance & Plan Reviewing: -Fine tuning strategy -Assess individual performance -Identify strength & weakness | F33: 1.7.1 | G33: Standarisasi kompetensi, tugas & tanggung jawab sales zone A & B dan SCO | H33: 1.7.1.1 | I33: 100% sales implementasi KPI dan WI sales zone A, B, C dan SCO Agen Mitra | K33: KACAB, SALES | L33: 0.03
F34: 1.7.2 | G34: Mencari & mengakuisisi leads sesuai dengan perkembangan ekonomi Indonesia | H34: 1.7.2.1 | I34: 3 New Cust/Sales (Monthly) | K34: KACAB, SALES | L34: 0.02
F35: 1.7.3 | G35: sosialisasi dan review skema incentive (rewarding) | H35: 1.7.3.1 | I35: 100% implementation of competitive scheme | J35: terbentuknya skema insentif yang kompetitif dan produktif utk team sales | K35: REGIONAL, KACAB, SALES | L35: 0.03
D36: 1.8 | E36: Drive Excellence in Sales: -Invest in team -Setting clear expectations -Effective process -Data driven | F36: 1.8.1 | G36: Mengimplementasikan upselling cross-sellling customer | H36: 1.8.1.1 | I36: 1 upselling/crosselling cust /month | K36: KACAB, SALES | L36: 0.02
F37: 1.8.2 | G37: Melakukan training rutin cross selling, upselling, cross cabang, cross direktorat, vertical training & external | H37: 1.8.2.1 | I37: 4 sesi/year development training | K37: REGIONAL, KACAB, SALES | L37: 0.03
H38: 1.8.2.2 | I38: 4 sesi/year refreshment training (ops, acc) | K38: REGIONAL, KACAB, SALES | L38: 0.03
H39: 1.8.2.3 | I39: Training AI for Sales Strategy, Digital Marketing. | J39: Meningkatkan Skill dan Kompetensi dalam pemanfaatan AI baik untuk branding, copywriting, marketing tools sehingga berimpact ke konversi leads dan volume, serta digital marketing. | K39: IT, HC | L39: 0.03
D40: 1.9 | E40: Developing Potential Growth: -Build customers relationship -Continuously develop zone B & C potential -Existing & New Opportunities (Marketplace & Social Commerce Potential), Lead Seller as Customers Besides Dealing with Marketplace; Developing Sales Business with Super Team, Know Customer Ecosystem | F40: 1.9.1 | G40: Corporate: -Mendapatkan lead -Mengelola pipeline -Bisa closing (solusi bisnis, pricing, customer requirement & handling) -Maintain (Upselling cross selling) | H40: 1.9.1.1 | I40: 100% Implementasi dan monitoring form 3MI | J40: Achieve Revenue Corp. 82M (82,329,496,370) Government 4M (4,158,841,388) MP 952M (952,677,001,357) Retail 204M (204,021,321,755) Social Commerce 107M (107,014,450,680) AMI : 35,224,759,577 DPS : 134,076,200,483 JBR : 64,446,762,863 KDR : 119,457,033,563 KOE : 35,369,011,351 LBJ : 16,135,919,415 MDN : 67,306,271,474 MJK : 63,971,903,678 MXG : 77,481,224,940 PBL : 31,972,715,527 PSR : 31,335,836,111 SDA : 130,217,043,996 SUB : 543,206,428,569 | K40: KACAB, SALES | L40: 0.03
H41: 1.9.1.2 | I41: 100% mapping cust dan implementasi tiering skema based on cust revenue, growth | K41: KACAB, SALES | L41: 0.02
H42: 1.9.1.3 | I42: specific periodical promo for top 3 customer corporate/pareto customer | K42: KACAB, SALES | L42: 0.02
F43: 1.9.2 | G43: E-commerce: -Memprioritaskan leads dari brand owner, komunitas & asosiasi -Pricing -Success rate (COD & NCOD) -On time delivery (SLA) -Intimasi seller -Irregularity (DWR, Damage, over SLA, Return) | H43: 1.9.2.1 | I43: 100% Implementasi dan monitoring form 3MI | K43: KACAB, SALES | L43: 0.03
...

Sheet Sheet2
D2: PEDOMAN MUTU
D3: PT.TIKI JALUR NUGRAHA EKAKURIR
D4: PROGRAM KERJA DEPARTEMEN / ANALIS
D5: Nomor : | F5: Revisi : 00 | K5: Departemen/Analis. | L5: :
D6: Tanggal Terbit : | F6: Halaman : 01/01 | K6: Divisi | L6: :
B8: NO. | C8: KEBIJAKAN MUTU | D8: SASARAN MUTU | F8: PROGRAM KERJA | H8: TARGET PENCAPAIAN Wajib Terukur - (Jumlah | Persentase | Waktu) | J8: OUTCOME | K8: PIC | L8: BOBOT (%) | M8: WAKTU
M9: Q1 | P9: Q2 | S9: Q3 | V9: Q4
M10: 1 | N10: 2 | O10: 3 | P10: 4 | Q10: 5 | R10: 6 | S10: 7 | T10: 8 | U10: 9 | V10: 10 | W10: 11 | X10: 12
B12: 1 | C12: DRIVEN GREAT BUSINESS OUTCOMES | D12: 1.1. | E12: Meningkatkan Penjualan (via performa layanan) | F12: 1.1.1 | G12: Dashboard performa delivery & penjualan | H12: 1.1.1.1 | I12: =Sheet1!D2 -> 100% inventaris kebutuhan bisnis + KPI awal; Data Source Inventory + mapping field; laporan baseline data quality & risiko + rencana mitigasi | J12: Keputusan penjualan lebih akurat karena fondasi data rapi; potensi “salah baca performa” turun | K12: BPS (Owner), Opr (validator proses), Head Section (approve scope) | L12: 0.05
H13: 1.1.1.2 | I13: =Sheet1!D3 -> 100% Susun rumus KPI + aturan bisnis, validasi hasil, bangun dashboard prototype + dokumentasi rule | J13: KPI seragam → tindakan perbaikan tidak debat definisi; kecepatan eksekusi naik | K13: BPS, Opr, Head Section | L13: 0.05
H14: 1.1.1.3 | I14: =Sheet1!D4 -> Monitoring harian & analisis tren | J14: Monitoring performa jadi “alat kerja harian”; temuan masalah lebih cepat | K14: BPS, Opr (UAT user), Head Section (acceptance) | L14: 0.05
H15: 1.1.1.4 | I15: =Sheet1!D5 -> min. 1 insight report/bulan + log perbaikan dashboard | J15: Insight rutin memicu perbaikan SLA → dampak ke repeat order & revenue | K15: BPS, Opr, Head Section | L15: 0.05
D16: 1.2. | E16: Meningkatkan Performance | F16: 1.2.1 | G16: Dashboard KPI operasional (FM/LM) | H16: 1.2.1.1 | I16: =Sheet1!D6 -> kebutuhan KPI terkumpul; daftar sumber data; gap requirement + rencana perbaikan | J16: Prioritas perbaikan operasional tajam (FM/LM), bukan sekadar feeling | K16: BPS, Opr FM/LM, Head Section | L16: 0.04
H17: 1.2.1.2 | I17: =Sheet1!D7 -> rumus KPI tervalidasi; crosscheck manual vs sistem; dashboard v1 + dokumen KPI | J17: Angka operasional kredibel; error pelaporan turun | K17: BPS, Opr | L17: 0.04
H18: 1.2.1.3 | I18: =Sheet1!D8 -> fitur kontrol aktif (filter, threshold, breakdown); dashboard stabil | J18: Kontrol operasional proaktif: deviasi cepat terlihat | K18: BPS, Opr | L18: 0.04
H19: 1.2.1.4 | I19: =Sheet1!D9 -> min. 1 insight report/bulan + daftar deviasi, rekomendasi, status tindak lanjut | J19: Deviasi KPI berkurang karena ada tindak lanjut terukur | K19: BPS, Opr, Head Section | L19: 0.06
F20: 1.2.2 | G20: KPI Dictionary & Single Source of Truth | H20: 1.2.2.1 | I20: =Sheet1!D10 -> Draft KPI Dictionary lengkap (tujuan, formula, sumber, frekuensi, batasan) | J20: Standar definisi KPI terbentuk | K20: BPS | L20: 0.03
H21: 1.2.2.2 | I21: =Sheet1!D11 -> Validasi lintas fungsi + tetapkan (Single Source of Truth) SSOT per KPI + disahkan | J21: 1 bahasa KPI untuk semua unit → rapat lebih efektif | K21: BPS, Head Section (approve) | L21: 0.03
G22: KPI Dictionary & Single Source of Truth | H22: 1.2.2.3 | I22: =Sheet1!D12 -> Des: review tahunan + audit konsistensi definisi KPI vs dashboard/laporan | J22: KPI tetap relevan; mencegah drift definisi | K22: BPS, Head Section | L22: 0.02
F23: 1.2.3 | G23: Digitalisasi isu operasional harian | H23: 1.2.3.1 | I23: =Sheet1!D13 -> form isu + taxonomy + alur eskalasi dasar | J23: Isu tidak hilang; eskalasi jelas; akuntabilitas naik | K23: Opr (Owner), BPS (support data), Head Section (escalation owner) | L23: 0.03
H24: 1.2.3.2 | I24: =Sheet1!D14 -> implementasi + dashboard isu awal (volume/kategori/penyelesaian) | J24: Pola masalah terlihat; penanganan lebih sistematis | K24: Opr, BPS | L24: 0.03
H25: 1.2.3.3 | I25: =Sheet1!D15 -> min. 1 laporan isu dominan/bulan + status penyelesaian rutin | J25: Penyelesaian isu lebih cepat; masalah berulang turun | K25: Opr, BPS, Head Section | L25: 0.04
F26: 1.2.4 | G26: Review & evaluasi KPI berkala | H26: 1.2.4.1 | I26: =Sheet1!D16 -> Q1 (Mar): notulen + action plan (PIC, due date, indikator sukses) | J26: Disiplin eksekusi perbaikan KPI | K26: Head Section (Owner), BPS (data), Opr (aksi) | L26: 0.02
H27: 1.2.4.2 | I27: =Sheet1!D17 -> Q2 (Mei): update status action plan + keputusan manajemen | J27: Hambatan dieksekusi, bukan ditunda | K27: Head Section, Opr, BPS | L27: 0.02
H28: 1.2.4.3 | I28: =Sheet1!D18 -> Mid-year (Juli): evaluasi semester + penyesuaian target/strategi | J28: Target tetap menantang & realistis | K28: Head Section | L28: 0.03
H29: 1.2.4.4 | I29: =Sheet1!D19 -> Q3 (Sep): kesiapan Q4 + daftar prioritas perbaikan | J29: Fokus Q4 terkunci, tidak melebar | K29: Head Section | L29: 0.02
H30: 1.2.4.5 | I30: =Sheet1!D20 -> Q4 (Nov): evaluasi akhir tahun + backlog improvement | J30: Continuous improvement terdokumentasi | K30: Head Section, BPS | L30: 0.03
F31: 1.2.5 | G31: Laporan Red Flag Bulanan | H31: 1.2.5.1 | I31: =Sheet1!D21 -> Jan–Des: 12 laporan; threshold KPI kritis + mitigasi + status | J31: Early warning aktif; mencegah eskalasi masalah besar | K31: BPS (Owner), Opr (aksi), Head Section (decision) | L31: 0.1
D32: 1.3. | E32: Menekan Cost to Serve & Produktivitas | F32: 1.3.1 | G32: Otomatisasi pengolahan data | H32: 1.3.1.1 | I32: =Sheet1!D22 -> baseline waktu/biaya/error + prioritas otomasi + proposal | J32: ROI otomasi jelas; fokus pada proses paling boros | K32: BPS, Opr | L32: 0.03
F33: 1.3.1 | H33: =Sheet1!A23 -> 1.3.1.2 | I33: =Sheet1!D23 -> Mar: MVP jadi + uji manual vs otomatis + panduan | J33: =Sheet1!E23 -> Pengolahan data lebih cepat & konsisten | K33: =Sheet1!F23 -> BPS, (IT bila perlu) | L33: 0.03
F34: 1.3.1 | H34: =Sheet1!A24 -> 1.3.1.3 | I34: =Sheet1!D24 -> Mar–Jun: Implementasi, training, monitoring error & perbaikan cepat + pengukuran efisiensi | J34: =Sheet1!E24 -> Beban kerja turun terukur; kualitas laporan naik | K34: =Sheet1!F24 -> BPS, Opr | L34: 0.02
F35: 1.3.1 | H35: =Sheet1!A25 -> 1.3.1.4 | I35: =Sheet1!D25 -> Penyempurnaan stabilitas, logging, exception handling, evaluasi benefit | J35: =Sheet1!E25 -> Laporan benefit efisiensi + proses manual berkurang signifikan | K35: =Sheet1!F25 -> BPS | L35: 0.02
F36: 1.3.2 | G36: Standardisasi proses admin/data | H36: =Sheet1!A26 -> 1.3.2.1 | I36: =Sheet1!D26 -> SOP + checklist kontrol | J36: =Sheet1!E26 -> Variasi cara kerja; audit-ready | K36: =Sheet1!F26 -> Opr (Owner), BPS (review kontrol) | L36: 0.02
F37: 1.3.2 | H37: =Sheet1!A27 -> 1.3.2.2 | I37: =Sheet1!D27 -> validasi lapangan + daftar bottleneck + rekomendasi | J37: =Sheet1!E27 -> SOP realistis & tepat guna | K37: =Sheet1!F27 -> Opr, Head Section | L37: 0.02
F38: 1.3.2 | H38: =Sheet1!A28 -> 1.3.2.3 | I38: =Sheet1!D28 -> Sosialisasi & implementasi SOP, monitoring kepatuhan, penyesuaian minor | J38: =Sheet1!E28 -> Proses seragam + bukti sosialisasi + laporan kepatuhan SOP | K38: =Sheet1!F28 -> Opr, Head Section | L38: 0.02
D39: 1.4. | E39: Naik Kelas & Membangun SDM | F39: 1.4.1 | G39: Diskusi data & insight rutin | H39: =Sheet1!A29 -> 1.4.1.1 | I39: =Sheet1!D29 -> Susun template diskusi: performa, risiko, rekomendasi, keputusan, action plan | J39: =Sheet1!E29 -> Template diskusi + format notulen & action plan standar | K39: =Sheet1!F29 -> Head Section, BPS | L39: 0.02
G40: BPS Sharing Knowledge (Internal Learning Session) | H40: 1.4.1.2 | I40: Min. 6 sesi/tahun (≥1 sesi/ 2 bulan) durasi 45–60 menit. Wajib: materi tersimpan, notulen+action points (≥3), daftar hadir (≥80% undangan), pre–post check (kenaikan skor rata-rata ≥20% / lulus ≥80%). Min. 6 sesi hands-on menghasilkan template/alat kerja. | J40: Kompetensi tim naik terukur; transfer knowledge konsisten; standar kerja seragam; error laporan turun & respon deviasi lebih cepat. | K40: BPS (Owner/Host), Head Section (Sponsor), Ops (Co-host/Case), IT (opsional) | L40: 0.04
L41: =SUM(L12:L40) -> 1

Sheet Sheet1
A1: Kode | B1: SASARAN MUTU | C1: PROGRAM KERJA | D1: TARGET PENCAPAIAN (wajib terukur) | E1: OUTCOME (dipertajam) | F1: PIC (lebih detail) | G1: BOBOT (%)
A2: 1.1.1.1 | B2: Meningkatkan Penjualan (via performa layanan) | C2: Dashboard performa delivery & penjualan | D2: 100% inventaris kebutuhan bisnis + KPI awal; Data Source Inventory + mapping field; laporan baseline data quality & risiko + rencana mitigasi | E2: Keputusan penjualan lebih akurat karena fondasi data rapi; potensi “salah baca performa” turun | F2: BPS (Owner), Opr (validator proses), Head Section (approve scope) | G2: 6
A3: 1.1.1.2 | B3: Meningkatkan Penjualan (via performa layanan) | C3: Dashboard performa delivery & penjualan | D3: 100% Susun rumus KPI + aturan bisnis, validasi hasil, bangun dashboard prototype + dokumentasi rule | E3: KPI seragam → tindakan perbaikan tidak debat definisi; kecepatan eksekusi naik | F3: BPS, Opr, Head Section | G3: 6
A4: 1.1.1.3 | B4: Meningkatkan Penjualan (via performa layanan) | C4: Dashboard performa delivery & penjualan | D4: Monitoring harian & analisis tren | E4: Monitoring performa jadi “alat kerja harian”; temuan masalah lebih cepat | F4: BPS, Opr (UAT user), Head Section (acceptance) | G4: 6
A5: 1.1.1.4 | B5: Meningkatkan Penjualan (via performa layanan) | C5: Dashboard performa delivery & penjualan | D5: min. 1 insight report/bulan + log perbaikan dashboard | E5: Insight rutin memicu perbaikan SLA → dampak ke repeat order & revenue | F5: BPS, Opr, Head Section | G5: 10
A6: 1.2.1.1 | B6: Meningkatkan Performance | C6: Dashboard KPI operasional (FM/LM) | D6: kebutuhan KPI terkumpul; daftar sumber data; gap requirement + rencana perbaikan | E6: Prioritas perbaikan operasional tajam (FM/LM), bukan sekadar feeling | F6: BPS, Opr FM/LM, Head Section | G6: 5
A7: 1.2.1.2 | B7: Meningkatkan Performance | C7: Dashboard KPI operasional (FM/LM) | D7: rumus KPI tervalidasi; crosscheck manual vs sistem; dashboard v1 + dokumen KPI | E7: Angka operasional kredibel; error pelaporan turun | F7: BPS, Opr | G7: 5
A8: 1.2.1.3 | B8: Meningkatkan Performance | C8: Dashboard KPI operasional (FM/LM) | D8: fitur kontrol aktif (filter, threshold, breakdown); dashboard stabil | E8: Kontrol operasional proaktif: deviasi cepat terlihat | F8: BPS, Opr | G8: 5
A9: 1.2.1.4 | B9: Meningkatkan Performance | C9: Dashboard KPI operasional (FM/LM) | D9: min. 1 insight report/bulan + daftar deviasi, rekomendasi, status tindak lanjut | E9: Deviasi KPI berkurang karena ada tindak lanjut terukur | F9: BPS, Opr, Head Section | G9: 10
A10: 1.2.2.1 | B10: Meningkatkan Performance | C10: KPI Dictionary & Single Source of Truth | D10: Draft KPI Dictionary lengkap (tujuan, formula, sumber, frekuensi, batasan) | E10: Standar definisi KPI terbentuk | F10: BPS | G10: 4
A11: 1.2.2.2 | B11: Meningkatkan Performance | C11: KPI Dictionary & Single Source of Truth | D11: Validasi lintas fungsi + tetapkan (Single Source of Truth) SSOT per KPI + disahkan | E11: 1 bahasa KPI untuk semua unit → rapat lebih efektif | F11: BPS, Head Section (approve) | G11: 5
A12: 1.2.2.3 | B12: Meningkatkan Performance | C12: KPI Dictionary & Single Source of Truth | D12: Des: review tahunan + audit konsistensi definisi KPI vs dashboard/laporan | E12: KPI tetap relevan; mencegah drift definisi | F12: BPS, Head Section | G12: 3
A13: 1.2.3.1 | B13: Meningkatkan Performance | C13: Digitalisasi isu operasional harian | D13: form isu + taxonomy + alur eskalasi dasar | E13: Isu tidak hilang; eskalasi jelas; akuntabilitas naik | F13: Opr (Owner), BPS (support data), Head Section (escalation owner) | G13: 4
... A29: 1.4.1.1 | B29: Naik Kelas & Membangun SDM | C29: Diskusi data & insight rutin | D29: Susun template diskusi: performa, risiko, rekomendasi, keputusan, action plan | E29: Template diskusi + format notulen & action plan standar | F29: Head Section, BPS | G29: 5
G31: =SUM(G2:G29) -> 143

Sheet Sheet3
A1: Kode | B1: SASARAN MUTU | C1: PROGRAM KERJA | D1: TARGET PENCAPAIAN (Wajib terpenuhi – jumlah/per waktu) | E1: OUTCOME | F1: PIC (lebih detail) | G1: BOBOT (%)
A2: 1.1.1.1 | B2: Meningkatkan Penjualan (via performa layanan) | C2: Dashboard performa delivery & penjualan | D2: Jan: 100% inventaris kebutuhan bisnis & definisi KPI awal. Data Source Inventory (internal/eksternal) + mapping field. Laporan baseline data quality & risiko data (missing, duplikasi, anomali, latency) + rencana mitigasi. | E2: Fondasi data valid; keputusan penjualan lebih akurat; potensi salah baca performa turun. | F2: BPS (Owner), Ops (validator proses), Head Section (approve scope) | G2: 6
A3: 1.1.1.2 | B3: Meningkatkan Penjualan (via performa layanan) | C3: Dashboard performa delivery & penjualan | D3: Feb: 100% rumus KPI (SLA, success rate, growth) + aturan bisnis (filter, periode, cut-off) tervalidasi & sign-off Ops/Sales/Management. Prototype dashboard + dokumentasi rule/assumption KPI. | E3: KPI satu bahasa; debat definisi berkurang; eksekusi perbaikan lebih cepat. | F3: BPS (Owner), Ops, Head Section | G3: 6
A4: 1.1.1.3 | B4: Meningkatkan Penjualan (via performa layanan) | C4: Dashboard performa delivery & penjualan | D4: Mar: UAT selesai (checklist UAT + changelog). Dashboard stabil (load time & query performa) + fitur filter & drill-down siap. Struktur halaman & standar warna/label final. | E4: Dashboard siap dipakai rutin; analisa penjualan lebih cepat & konsisten. | F4: BPS (Owner), Ops (UAT user), Head Section (acceptance) | G4: 6
A5: 1.1.1.4 | B5: Meningkatkan Penjualan (via performa layanan) | C5: Dashboard performa delivery & penjualan | D5: Apr–Des: Monitoring rutin. Minimal 1 laporan insight/bulan (tren, outlier, akar penyebab, peluang/risiko) + log perbaikan dashboard & kontrol konsistensi definisi KPI. | E5: Perbaikan SLA/konversi berbasis insight; retensi & revenue terdorong karena layanan lebih stabil. | F5: BPS (Owner), Ops, Head Section | G5: 10
A6: 1.2.1.1 | B6: Meningkatkan Performance | C6: Dashboard KPI operasional (FM/LM) | D6: Jan: 100% kebutuhan KPI operasional per fungsi (Firstmile & Lastmile) terkumpul. Daftar data source + mapping field. Assessment kualitas data + daftar gap requirement + rencana perbaikan. | E6: Prioritas perbaikan operasional lebih tajam; kontrol FM/LM berbasis data. | F6: BPS (Owner), Ops FM/LM, Head Section | G6: 5
A7: 1.2.1.2 | B7: Meningkatkan Performance | C7: Dashboard KPI operasional (FM/LM) | D7: Feb: 100% rumus KPI operasional tervalidasi. Crosscheck angka vs laporan manual/sistem. Dashboard versi awal + dokumentasi KPI. | E7: Angka operasional kredibel; error pelaporan turun; tindakan lebih tepat. | F7: BPS (Owner), Ops | G7: 5
A8: 1.2.1.3 | B8: Meningkatkan Performance | C8: Dashboard KPI operasional (FM/LM) | D8: Mar: Penyempurnaan visual & performa. Fitur kontrol aktif (filter, threshold alert sederhana, breakdown root cause). Dashboard stabil & siap dipakai pengambilan keputusan. | E8: Kontrol operasional proaktif; deviasi cepat terdeteksi. | F8: BPS (Owner), Ops | G8: 5
A9: 1.2.1.4 | B9: Meningkatkan Performance | C9: Dashboard KPI operasional (FM/LM) | D9: Apr–Des: Monitoring tren KPI rutin. Minimal 1 insight report/bulan + daftar deviasi KPI, rekomendasi perbaikan proses, status tindak lanjut. | E9: Deviasi KPI berkurang karena tindak lanjut terukur; SLA naik lebih konsisten. | F9: BPS (Owner), Ops, Head Section | G9: 10
A10: 1.2.2.1 | B10: Meningkatkan Performance | C10: KPI Dictionary & Single Source of Truth | D10: Jan: Draft KPI Dictionary lengkap (tujuan, formula, satuan, sumber data, frekuensi update, PIC, batasan, contoh hitung). | E10: Standar definisi KPI terbentuk; mencegah multi-tafsir sejak awal. | F10: BPS (Owner) | G10: 4
A11: 1.2.2.2 | B11: Meningkatkan Performance | C11: KPI Dictionary & Single Source of Truth | D11: Feb: Validasi lintas fungsi (Ops, Sales, Management). Hilangkan definisi ganda. Tetapkan single source of truth per KPI. KPI Dictionary disahkan. | E11: 1 bahasa KPI; rapat lebih efektif; keputusan lebih cepat & minim konflik data. | F11: BPS (Owner), Head Section (approve) | G11: 5
A12: 1.2.2.3 | B12: Meningkatkan Performance | C12: KPI Dictionary & Single Source of Truth | D12: Des: Review tahunan + update definisi bila ada perubahan proses/sistem. Audit konsistensi definisi KPI vs dashboard & laporan manajemen. | E12: KPI tetap relevan; mencegah drift definisi & inkonsistensi laporan. | F12: BPS (Owner), Head Section | G12: 3
A13: 1.2.3.1 | B13: Meningkatkan Performance | C13: Digitalisasi isu operasional harian | D13: Jan: Form input isu tersedia (kategori, severity, dampak, lokasi, unit, waktu kejadian, PIC follow-up). Taxonomy kategori isu + alur eskalasi dasar. | E13: Isu tidak hilang; eskalasi jelas; akuntabilitas naik. | F13: Ops (Owner), BPS (support data), Head Section (escalation owner) | G13: 4
... A29: 1.4.1.1 | B29: Naik Kelas & Membangun SDM | C29: Diskusi data & insight rutin | D29: Jan: Susun template materi diskusi (ringkasan performa, risiko, rekomendasi, keputusan, action plan) + format notulen standar. | E29: Budaya data-driven terbentuk; koordinasi lebih efektif & terstruktur. | F29: Head Section (Owner), BPS | G29: 5
G32: =SUM(G2:G29) -> 143

Sheet Sheet4
A1: Kode | B1: PILAR SASARAN MUTU (Style Gambar 1) | C1: PROGRAM STRATEGIS | D1: RINGKAS TARGET (wajib terukur) | E1: OUTCOME STRATEGIS | F1: PIC | G1: Bobot (%)
A2: C-1 | B2: Build Business Outcomes: Revenue Growth via Service Performance | C2: Dashboard performa delivery & penjualan | D2: Q1 selesai: inventory data+KPI, sign-off definisi, UAT. Apr–Des: minimal 1 insight report/bulan + log perbaikan. | E2: Revenue terdorong lewat stabilitas SLA, peningkatan konversi layanan, dan retensi. | F2: BPS (Owner), Ops, Head Section | G2: 28
A3: C-2 | B3: Build Customer Outcomes: Satisfaction & Retention | C3: Digitalisasi isu operasional harian | D3: Jan–Mar: form+taxonomy+dashboard isu. Apr–Des: minimal 1 laporan isu dominan/bulan + status penyelesaian. | E3: Respon cepat, isu tidak hilang, masalah berulang turun → kepuasan & loyalitas naik. | F3: Ops (Owner), BPS, Head Section | G3: 14
A4: C-3 | B4: Build Customer Outcomes: Trust & Early Warning | C4: Laporan Red Flag Bulanan | D4: 12 laporan/tahun + threshold KPI kritis + mitigasi + status tindak lanjut. | E4: Early warning menjaga reputasi layanan & mencegah eskalasi. | F4: BPS (Owner), Ops, Head Section | G4: 12
A5: C-4 | B5: Drive Excellence: Cost to Serve turun | C5: Otomatisasi pengolahan data | D5: Baseline→MVP→implementasi→stabilisasi; efisiensi waktu/error terukur vs baseline. | E5: Produktivitas naik; reporting cepat; human error turun. | F5: BPS (Owner), Ops, IT (opsional) | G5: 18
A6: C-5 | B6: Drive Excellence: Proses stabil & audit-ready | C6: Standardisasi proses admin/data | D6: SOP+validasi lapangan+sosialisasi+monitor kepatuhan. | E6: Variasi kerja turun; kontrol internal naik; proses lebih stabil. | F6: Ops (Owner), Head Section, BPS (kontrol) | G6: 14
A7: C-6 | B7: Develop People & Governance: SSOT & Decision Cadence | C7: KPI Dictionary + Review KPI berkala + Diskusi insight | D7: KPI dictionary disahkan + review tahunan; review Q1/Q2/Mid/Q3/Q4 dengan notulen & action plan terukur. | E7: KPI satu bahasa; ritme perbaikan terjaga; budaya data-driven kuat. | F7: Head Section (Owner), BPS, Ops | G7: 14
G10: =SUM(G2:G7) -> 100

Sheet Sheet5
A1: Kode | B1: SASARAN MUTU | C1: PROGRAM KERJA | D1: TARGET PENCAPAIAN (Wajib terpenuhi – jumlah/per waktu) | E1: OUTCOME | F1: PIC (lebih detail) | G1: BOBOT (%)
A2: 1.1.1.1 | B2: Meningkatkan Penjualan (via performa layanan) | C2: Dashboard performa delivery & penjualan | D2: Jan: 100% inventaris kebutuhan bisnis & definisi KPI awal. Data Source Inventory (internal/eksternal) + mapping field. Laporan baseline data quality & risiko data (missing, duplikasi, anomali, latency) + rencana mitigasi. | E2: Fondasi data valid; keputusan penjualan lebih akurat; potensi salah baca performa turun. | F2: BPS (Owner), Ops (validator proses), Head Section (approve scope) | G2: 5
A3: 1.1.1.2 | B3: Meningkatkan Penjualan (via performa layanan) | C3: Dashboard performa delivery & penjualan | D3: Feb: 100% rumus KPI (SLA, success rate, growth) + aturan bisnis (filter, periode, cut-off) tervalidasi & sign-off Ops/Sales/Management. Prototype dashboard + dokumentasi rule/assumption KPI. | E3: KPI satu bahasa; debat definisi berkurang; eksekusi perbaikan lebih cepat. | F3: BPS (Owner), Ops, Head Section | G3: 5
A4: 1.1.1.3 | B4: Meningkatkan Penjualan (via performa layanan) | C4: Dashboard performa delivery & penjualan | D4: Mar: UAT selesai (checklist UAT + changelog). Dashboard stabil (load time & query performa) + fitur filter & drill-down siap. Struktur halaman & standar warna/label final. | E4: Dashboard siap dipakai rutin; analisa penjualan lebih cepat & konsisten. | F4: BPS (Owner), Ops (UAT user), Head Section (acceptance) | G4: 5
A5: 1.1.1.4 | B5: Meningkatkan Penjualan (via performa layanan) | C5: Dashboard performa delivery & penjualan | D5: Apr–Des: Monitoring rutin. Minimal 1 laporan insight/bulan (tren, outlier, akar penyebab, peluang/risiko) + log perbaikan dashboard & kontrol konsistensi definisi KPI. | E5: Perbaikan SLA/konversi berbasis insight; retensi & revenue terdorong karena layanan lebih stabil. | F5: BPS (Owner), Ops, Head Section | G5: 5
A6: 1.2.1.1 | B6: Meningkatkan Performance | C6: Dashboard KPI operasional (FM/LM) | D6: Jan: 100% kebutuhan KPI operasional per fungsi (Firstmile & Lastmile) terkumpul. Daftar data source + mapping field. Assessment kualitas data + daftar gap requirement + rencana perbaikan. | E6: Prioritas perbaikan operasional lebih tajam; kontrol FM/LM berbasis data. | F6: BPS (Owner), Ops FM/LM, Head Section | G6: 4
A7: 1.2.1.2 | B7: Meningkatkan Performance | C7: Dashboard KPI operasional (FM/LM) | D7: Feb: 100% rumus KPI operasional tervalidasi. Crosscheck angka vs laporan manual/sistem. Dashboard versi awal + dokumentasi KPI. | E7: Angka operasional kredibel; error pelaporan turun; tindakan lebih tepat. | F7: BPS (Owner), Ops | G7: 4
A8: 1.2.1.3 | B8: Meningkatkan Performance | C8: Dashboard KPI operasional (FM/LM) | D8: Mar: Penyempurnaan visual & performa. Fitur kontrol aktif (filter, threshold alert sederhana, breakdown root cause). Dashboard stabil & siap dipakai pengambilan keputusan. | E8: Kontrol operasional proaktif; deviasi cepat terdeteksi. | F8: BPS (Owner), Ops | G8: 4
A9: 1.2.1.4 | B9: Meningkatkan Performance | C9: Dashboard KPI operasional (FM/LM) | D9: Apr–Des: Monitoring tren KPI rutin. Minimal 1 insight report/bulan + daftar deviasi KPI, rekomendasi perbaikan proses, status tindak lanjut. | E9: Deviasi KPI berkurang karena tindak lanjut terukur; SLA naik lebih konsisten. | F9: BPS (Owner), Ops, Head Section | G9: 6
A10: 1.2.2.1 | B10: Meningkatkan Performance | C10: KPI Dictionary & Single Source of Truth | D10: Jan: Draft KPI Dictionary lengkap (tujuan, formula, satuan, sumber data, frekuensi update, PIC, batasan, contoh hitung). | E10: Standar definisi KPI terbentuk; mencegah multi-tafsir sejak awal. | F10: BPS (Owner) | G10: 3
A11: 1.2.2.2 | B11: Meningkatkan Performance | C11: KPI Dictionary & Single Source of Truth | D11: Feb: Validasi lintas fungsi (Ops, Sales, Management). Hilangkan definisi ganda. Tetapkan single source of truth per KPI. KPI Dictionary disahkan. | E11: 1 bahasa KPI; rapat lebih efektif; keputusan lebih cepat & minim konflik data. | F11: BPS (Owner), Head Section (approve) | G11: 3
A12: 1.2.2.3 | B12: Meningkatkan Performance | C12: KPI Dictionary & Single Source of Truth | D12: Des: Review tahunan + update definisi bila ada perubahan proses/sistem. Audit konsistensi definisi KPI vs dashboard & laporan manajemen. | E12: KPI tetap relevan; mencegah drift definisi & inkonsistensi laporan. | F12: BPS (Owner), Head Section | G12: 2
A13: 1.2.3.1 | B13: Meningkatkan Performance | C13: Digitalisasi isu operasional harian | D13: Jan: Form input isu tersedia (kategori, severity, dampak, lokasi, unit, waktu kejadian, PIC follow-up). Taxonomy kategori isu + alur eskalasi dasar. | E13: Isu tidak hilang; eskalasi jelas; akuntabilitas naik. | F13: Ops (Owner), BPS (support data), Head Section (escalation owner) | G13: 3
... A29: 1.4.1.1 | B29: Naik Kelas & Membangun SDM | C29: Diskusi data & insight rutin | D29: Jan: Susun template materi diskusi (ringkasan performa, risiko, rekomendasi, keputusan, action plan) + format notulen standar. | E29: Budaya data-driven terbentuk; koordinasi lebih efektif & terstruktur. | F29: Head Section (Owner), BPS | G29: 4
