Workbook
Name AMOUNTALORLUNAS24: #REF!
Name AMOUNTALOROTS24: #REF!
Name AMT_BTN_LUNAS24: [1]LUNAS!$K$1:$K$65536
Name AMT_BTN_OTS24: [1]OTS!$K$1:$K$65536
Name AMT_LBJ_LUNAS24: [2]LUNAS!$K$1:$K$65536
Name AMT_LBJ_OTS24: [2]OTS!$K$1:$K$65536
Name AMT_LKA_LUNAS24: [3]LUNAS!$K$1:$K$65536
Name AMT_LKA_OTS24: [3]OTS!$K$1:$K$65536
Name DATE_BTN_LUNAS24: [1]LUNAS!$C$1:$C$65536
Name DATE_BTN_OTS24: [1]OTS!$C$1:$C$65536
Name DATE_LBJ_LUNAS24: [2]LUNAS!$C$1:$C$65536
Name DATE_LBJ_OTS24: [2]OTS!$C$1:$C$65536
Name DATE_LKA_LUNAS24: [3]LUNAS!$C$1:$C$65536
Name DATE_LKA_OTS24: [3]OTS!$C$1:$C$65536
Name DATEALORLUNAS24: #REF!
Name DATEALOROTS24: #REF!

Sheet ALOR 2026
A1: TOTAL | C1: SETORAN BANK | F1: =SUBTOTAL(9,F3:F405) -> 263506486
A2: Hari | B2: Tanggal | C2: BRI | D2: BNI | E2: LAINNYA | F2: TOTAL SETORAN
A3: 46023 | B3: 46023 | F3: =SUM('ALOR 2026'!$C3:$E3) -> 0
A4: 46024 | B4: 46024 | F4: =SUM('ALOR 2026'!$C4:$E4) -> 0
A5: 46025 | B5: 46025 | F5: =SUM('ALOR 2026'!$C5:$E5) -> 0
A6: 46026 | B6: 46026 | F6: =SUM('ALOR 2026'!$C6:$E6) -> 0
A7: 46027 | B7: 46027 | C7: =9374682+1933825+12860304+1236150 -> 25404961 | F7: =SUM('ALOR 2026'!$C7:$E7) -> 25404961
A8: 46028 | B8: 46028 | F8: =SUM('ALOR 2026'!$C8:$E8) -> 0
A9: 46029 | B9: 46029 | F9: =SUM('ALOR 2026'!$C9:$E9) -> 0
A10: 46030 | B10: 46030 | C10: =14157107+8984468 -> 23141575 | F10: =SUM('ALOR 2026'!$C10:$E10) -> 23141575
A11: 46031 | B11: 46031 | C11: =5648896 -> 5648896 | F11: =SUM('ALOR 2026'!$C11:$E11) -> 5648896
A12: 46032 | B12: 46032 | F12: =SUM('ALOR 2026'!$C12:$E12) -> 0
A13: 46033 | B13: 46033 | F13: =SUM('ALOR 2026'!$C13:$E13) -> 0
A14: 46034 | B14: 46034 | F14: =SUM('ALOR 2026'!$C14:$E14) -> 0
A15: 46035 | B15: 46035 | C15: =11902982+7561415 -> 19464397 | F15: =SUM('ALOR 2026'!$C15:$E15) -> 19464397
A16: 46036 | B16: 46036 | F16: =SUM('ALOR 2026'!$C16:$E16) -> 0
A17: 46037 | B17: 46037 | C17: =6841540 -> 6841540 | F17: =SUM('ALOR 2026'!$C17:$E17) -> 6841540
A18: 46038 | B18: 46038 | F18: =SUM('ALOR 2026'!$C18:$E18) -> 0
A19: 46039 | B19: 46039 | F19: =SUM('ALOR 2026'!$C19:$E19) -> 0
A20: 46040 | B20: 46040 | F20: =SUM('ALOR 2026'!$C20:$E20) -> 0
A21: 46041 | B21: 46041 | C21: =10419756+2010173 -> 12429929 | F21: =SUM('ALOR 2026'!$C21:$E21) -> 12429929
A22: 46042 | B22: 46042 | F22: =SUM('ALOR 2026'!$C22:$E22) -> 0
A23: 46043 | B23: 46043 | F23: =SUM('ALOR 2026'!$C23:$E23) -> 0
A24: 46044 | B24: 46044 | F24: =SUM('ALOR 2026'!$C24:$E24) -> 0
A25: 46045 | B25: 46045 | C25: =4683000+1287000 -> 5970000 | F25: =SUM('ALOR 2026'!$C25:$E25) -> 5970000
A26: 46046 | B26: 46046 | F26: =SUM('ALOR 2026'!$C26:$E26) -> 0
A27: 46047 | B27: 46047 | F27: =SUM('ALOR 2026'!$C27:$E27) -> 0
A28: 46048 | B28: 46048 | F28: =SUM('ALOR 2026'!$C28:$E28) -> 0
A29: 46049 | B29: 46049 | C29: =3153000 -> 3153000 | F29: =SUM('ALOR 2026'!$C29:$E29) -> 3153000
A30: 46050 | B30: 46050 | F30: =SUM('ALOR 2026'!$C30:$E30) -> 0
A31: 46051 | B31: 46051 | C31: =28428832 -> 28428832 | F31: =SUM('ALOR 2026'!$C31:$E31) -> 28428832
A32: 46052 | B32: 46052 | C32: =3821564 -> 3821564 | F32: =SUM('ALOR 2026'!$C32:$E32) -> 3821564
A33: 46053 | B33: 46053 | F33: =SUM('ALOR 2026'!$C33:$E33) -> 0
A34: 46054 | B34: 46054 | F34: =SUM('ALOR 2026'!$C34:$E34) -> 0
A35: 46055 | B35: 46055 | C35: =16033853+3589475+3938665 -> 23561993 | F35: =SUM('ALOR 2026'!$C35:$E35) -> 23561993
A36: 46056 | B36: 46056 | F36: =SUM('ALOR 2026'!$C36:$E36) -> 0
A37: 46057 | B37: 46057 | C37: =17537706 -> 17537706 | F37: =SUM('ALOR 2026'!$C37:$E37) -> 17537706
A38: 46058 | B38: 46058 | F38: =SUM('ALOR 2026'!$C38:$E38) -> 0
A39: 46059 | B39: 46059 | C39: =7535467 -> 7535467 | F39: =SUM('ALOR 2026'!$C39:$E39) -> 7535467
A40: 46060 | B40: 46060 | F40: =SUM('ALOR 2026'!$C40:$E40) -> 0
...

Sheet ATAMBUA 2026
A1: TOTAL | C1: SETORAN BANK | F1: =SUBTOTAL(9,F3:F393) -> 338220541
A2: Hari | B2: Tanggal | C2: BRI | D2: BNI | E2: LAINNYA | F2: TOTAL SETORAN
A3: 46023 | B3: 46023 | F3: =SUM('ATAMBUA 2026'!$C3:$E3) -> 0
A4: 46024 | B4: 46024 | D4: =5756702 -> 5756702 | F4: =SUM('ATAMBUA 2026'!$C4:$E4) -> 5756702
A5: 46025 | B5: 46025 | F5: =SUM('ATAMBUA 2026'!$C5:$E5) -> 0
A6: 46026 | B6: 46026 | F6: =SUM('ATAMBUA 2026'!$C6:$E6) -> 0
A7: 46027 | B7: 46027 | D7: =18593993 -> 18593993 | F7: =SUM('ATAMBUA 2026'!$C7:$E7) -> 18593993
A8: 46028 | B8: 46028 | F8: =SUM('ATAMBUA 2026'!$C8:$E8) -> 0
A9: 46029 | B9: 46029 | D9: =10515492 -> 10515492 | F9: =SUM('ATAMBUA 2026'!$C9:$E9) -> 10515492
A10: 46030 | B10: 46030 | F10: =SUM('ATAMBUA 2026'!$C10:$E10) -> 0
A11: 46031 | B11: 46031 | D11: =13798443 -> 13798443 | F11: =SUM('ATAMBUA 2026'!$C11:$E11) -> 13798443
A12: 46032 | B12: 46032 | F12: =SUM('ATAMBUA 2026'!$C12:$E12) -> 0
A13: 46033 | B13: 46033 | F13: =SUM('ATAMBUA 2026'!$C13:$E13) -> 0
A14: 46034 | B14: 46034 | D14: =21080767 -> 21080767 | F14: =SUM('ATAMBUA 2026'!$C14:$E14) -> 21080767
A15: 46035 | B15: 46035 | F15: =SUM('ATAMBUA 2026'!$C15:$E15) -> 0
A16: 46036 | B16: 46036 | D16: =10518492 -> 10518492 | F16: =SUM('ATAMBUA 2026'!$C16:$E16) -> 10518492
A17: 46037 | B17: 46037 | D17: =4273153 -> 4273153 | F17: =SUM('ATAMBUA 2026'!$C17:$E17) -> 4273153
A18: 46038 | B18: 46038 | D18: =100000 -> 100000 | F18: =SUM('ATAMBUA 2026'!$C18:$E18) -> 100000
A19: 46039 | B19: 46039 | F19: =SUM('ATAMBUA 2026'!$C19:$E19) -> 0
A20: 46040 | B20: 46040 | F20: =SUM('ATAMBUA 2026'!$C20:$E20) -> 0
A21: 46041 | B21: 46041 | D21: =22356760 -> 22356760 | F21: =SUM('ATAMBUA 2026'!$C21:$E21) -> 22356760
A22: 46042 | B22: 46042 | F22: =SUM('ATAMBUA 2026'!$C22:$E22) -> 0
A23: 46043 | B23: 46043 | D23: =11621041 -> 11621041 | F23: =SUM('ATAMBUA 2026'!$C23:$E23) -> 11621041
A24: 46044 | B24: 46044 | F24: =SUM('ATAMBUA 2026'!$C24:$E24) -> 0
A25: 46045 | B25: 46045 | D25: =21328140 -> 21328140 | F25: =SUM('ATAMBUA 2026'!$C25:$E25) -> 21328140
A26: 46046 | B26: 46046 | F26: =SUM('ATAMBUA 2026'!$C26:$E26) -> 0
A27: 46047 | B27: 46047 | F27: =SUM('ATAMBUA 2026'!$C27:$E27) -> 0
A28: 46048 | B28: 46048 | D28: =25567350 -> 25567350 | F28: =SUM('ATAMBUA 2026'!$C28:$E28) -> 25567350
A29: 46049 | B29: 46049 | F29: =SUM('ATAMBUA 2026'!$C29:$E29) -> 0
A30: 46050 | B30: 46050 | D30: =12064679 -> 12064679 | F30: =SUM('ATAMBUA 2026'!$C30:$E30) -> 12064679
A31: 46051 | B31: 46051 | D31: =3347000 -> 3347000 | F31: =SUM('ATAMBUA 2026'!$C31:$E31) -> 3347000
A32: 46052 | B32: 46052 | D32: =9436611 -> 9436611 | F32: =SUM('ATAMBUA 2026'!$C32:$E32) -> 9436611
A33: 46053 | B33: 46053 | F33: =SUM('ATAMBUA 2026'!$C33:$E33) -> 0
A34: 46054 | B34: 46054 | F34: =SUM('ATAMBUA 2026'!$C34:$E34) -> 0
A35: 46055 | B35: 46055 | D35: =15991113+540000 -> 16531113 | F35: =SUM('ATAMBUA 2026'!$C35:$E35) -> 16531113
A36: 46056 | B36: 46056 | F36: =SUM('ATAMBUA 2026'!$C36:$E36) -> 0
A37: 46057 | B37: 46057 | D37: =11838230 -> 11838230 | F37: =SUM('ATAMBUA 2026'!$C37:$E37) -> 11838230
A38: 46058 | B38: 46058 | F38: =SUM('ATAMBUA 2026'!$C38:$E38) -> 0
A39: 46059 | B39: 46059 | D39: =7273385 -> 7273385 | F39: =SUM('ATAMBUA 2026'!$C39:$E39) -> 7273385
A40: 46060 | B40: 46060 | F40: =SUM('ATAMBUA 2026'!$C40:$E40) -> 0
...

Sheet BETUN 2026
A1: TOTAL | C1: SETORAN BANK | F1: =SUBTOTAL(9,F3:F405) -> 129121890
A2: Hari | B2: Tanggal | C2: BRI | D2: BNI | E2: LAINNYA | F2: TOTAL SETORAN
A3: 46023 | B3: 46023 | F3: =SUM('BETUN 2026'!$C3:$E3) -> 0
A4: 46024 | B4: 46024 | D4: =378000+1947345+21000+1000000+21000+75000 -> 3442345 | F4: =SUM('BETUN 2026'!$C4:$E4) -> 3442345
A5: 46025 | B5: 46025 | F5: =SUM('BETUN 2026'!$C5:$E5) -> 0
A6: 46026 | B6: 46026 | C6: =79000 -> 79000 | D6: =63000+21000+50000 -> 134000 | F6: =SUM('BETUN 2026'!$C6:$E6) -> 213000
A7: 46027 | B7: 46027 | D7: =100000+4946545+44000+150000+11000+377600+21000+100000 -> 5750145 | F7: =SUM('BETUN 2026'!$C7:$E7) -> 5750145
A8: 46028 | B8: 46028 | C8: =270000 -> 270000 | D8: =103000+200000 -> 303000 | F8: =SUM('BETUN 2026'!$C8:$E8) -> 573000
A9: 46029 | B9: 46029 | D9: =400000+5576927+250000+21000+51000 -> 6298927 | F9: =SUM('BETUN 2026'!$C9:$E9) -> 6298927
A10: 46030 | B10: 46030 | C10: =11000 -> 11000 | D10: =50000+11000+300000+50000+63000 -> 474000 | F10: =SUM('BETUN 2026'!$C10:$E10) -> 485000
A11: 46031 | B11: 46031 | C11: =41000 -> 41000 | D11: =3439785+50000+41000+792000+50000 -> 4372785 | F11: =SUM('BETUN 2026'!$C11:$E11) -> 4413785
A12: 46032 | B12: 46032 | C12: =21000+183000 -> 204000 | D12: =21000+150000+150000+50000 -> 371000 | F12: =SUM('BETUN 2026'!$C12:$E12) -> 575000
A13: 46033 | B13: 46033 | C13: =21000 -> 21000 | D13: =100000+50000+21000+21000+250000 -> 442000 | F13: =SUM('BETUN 2026'!$C13:$E13) -> 463000
A14: 46034 | B14: 46034 | C14: =21000 -> 21000 | D14: =4536834+478775+21000+21000+63000+47000 -> 5167609 | F14: =SUM('BETUN 2026'!$C14:$E14) -> 5188609
A15: 46035 | B15: 46035 | C15: =42000+348700 -> 390700 | D15: =500000+62000+21000+21000 -> 604000 | F15: =SUM('BETUN 2026'!$C15:$E15) -> 994700
A16: 46036 | B16: 46036 | D16: =4148919+21000+250000+41000+42000 -> 4502919 | F16: =SUM('BETUN 2026'!$C16:$E16) -> 4502919
A17: 46037 | B17: 46037 | D17: =25000+21000+340800 -> 386800 | F17: =SUM('BETUN 2026'!$C17:$E17) -> 386800
A18: 46038 | B18: 46038 | D18: =21000+21000+21000+83000+21000 -> 167000 | F18: =SUM('BETUN 2026'!$C18:$E18) -> 167000
A19: 46039 | B19: 46039 | D19: =500000+21000+175000+202000 -> 898000 | F19: =SUM('BETUN 2026'!$C19:$E19) -> 898000
A20: 46040 | B20: 46040 | C20: =21000 -> 21000 | D20: =229000+21000+21000+21000+21000+21000+10000 -> 344000 | F20: =SUM('BETUN 2026'!$C20:$E20) -> 365000
A21: 46041 | B21: 46041 | D21: =7688981+50000+52000 -> 7790981 | F21: =SUM('BETUN 2026'!$C21:$E21) -> 7790981
A22: 46042 | B22: 46042 | D22: =100000+97000+205000 -> 402000 | F22: =SUM('BETUN 2026'!$C22:$E22) -> 402000
A23: 46043 | B23: 46043 | D23: =6600126+200000+97000+21000 -> 6918126 | F23: =SUM('BETUN 2026'!$C23:$E23) -> 6918126
A24: 46044 | B24: 46044 | D24: =700000+50000+21000+79000+21000 -> 871000 | F24: =SUM('BETUN 2026'!$C24:$E24) -> 871000
A25: 46045 | B25: 46045 | D25: =2135160+21000+21000+50000+102999 -> 2330159 | F25: =SUM('BETUN 2026'!$C25:$E25) -> 2330159
A26: 46046 | B26: 46046 | C26: =21000 -> 21000 | D26: =180000+100000 -> 280000 | F26: =SUM('BETUN 2026'!$C26:$E26) -> 301000
A27: 46047 | B27: 46047 | C27: =21000+21000+114000+21000 -> 177000 | D27: =21000+102000+69000+40000 -> 232000 | F27: =SUM('BETUN 2026'!$C27:$E27) -> 409000
A28: 46048 | B28: 46048 | D28: =5558455+625000+300000+21000+400000 -> 6904455 | F28: =SUM('BETUN 2026'!$C28:$E28) -> 6904455
A29: 46049 | B29: 46049 | D29: =21000+181000+21000 -> 223000 | F29: =SUM('BETUN 2026'!$C29:$E29) -> 223000
A30: 46050 | B30: 46050 | C30: =26000 -> 26000 | D30: =4885475+21000+45000+21000+21000 -> 4993475 | F30: =SUM('BETUN 2026'!$C30:$E30) -> 5019475
A31: 46051 | B31: 46051 | D31: =100000+21000 -> 121000 | F31: =SUM('BETUN 2026'!$C31:$E31) -> 121000
A32: 46052 | B32: 46052 | D32: =3264835+32000+21000+21000+41000+21000+21000+100000+21000+21000 -> 3563835 | F32: =SUM('BETUN 2026'!$C32:$E32) -> 3563835
A33: 46053 | B33: 46053 | D33: =230000+21000+21000+20000+21000 -> 313000 | F33: =SUM('BETUN 2026'!$C33:$E33) -> 313000
A34: 46054 | B34: 46054 | D34: =21000+150000 -> 171000 | F34: =SUM('BETUN 2026'!$C34:$E34) -> 171000
A35: 46055 | B35: 46055 | D35: =21000+5326279+303475+50000 -> 5700754 | F35: =SUM('BETUN 2026'!$C35:$E35) -> 5700754
A36: 46056 | B36: 46056 | D36: =21000+21000 -> 42000 | F36: =SUM('BETUN 2026'!$C36:$E36) -> 42000
A37: 46057 | B37: 46057 | C37: =90000 -> 90000 | D37: =3399648+42000+21000+21000 -> 3483648 | F37: =SUM('BETUN 2026'!$C37:$E37) -> 3573648
A38: 46058 | B38: 46058 | D38: =100000+21000+50000+21000 -> 192000 | F38: =SUM('BETUN 2026'!$C38:$E38) -> 192000
A39: 46059 | B39: 46059 | C39: =41000 -> 41000 | D39: =3312461+21000+21000+21000+40000+50000+20000+300000+279000+21000+44000 -> 4129461 | F39: =SUM('BETUN 2026'!$C39:$E39) -> 4170461
A40: 46060 | B40: 46060 | C40: =21000 -> 21000 | D40: =21000+41000+200000+39000 -> 301000 | F40: =SUM('BETUN 2026'!$C40:$E40) -> 322000
...

Sheet KEFA 2026
A1: TOTAL | C1: SETORAN BANK | F1: =SUBTOTAL(9,F3:F400) -> 273973335
A2: Hari | B2: Tanggal | C2: BRI | D2: BNI | E2: LAINNYA | F2: TOTAL SETORAN
A3: 46023 | B3: 46023 | F3: =SUM('KEFA 2026'!$C3:$E3) -> 0
A4: 46024 | B4: 46024 | D4: =3552000+21000 -> 3573000 | F4: =SUM('KEFA 2026'!$C4:$E4) -> 3573000
A5: 46025 | B5: 46025 | C5: =999000+222000 -> 1221000 | F5: =SUM('KEFA 2026'!$C5:$E5) -> 1221000
A6: 46026 | B6: 46026 | C6: =21000 -> 21000 | F6: =SUM('KEFA 2026'!$C6:$E6) -> 21000
A7: 46027 | B7: 46027 | D7: =9561000 -> 9561000 | F7: =SUM('KEFA 2026'!$C7:$E7) -> 9561000
A8: 46028 | B8: 46028 | C8: =85000+21000+21000+318000+21000+21000 -> 487000 | F8: =SUM('KEFA 2026'!$C8:$E8) -> 487000
A9: 46029 | B9: 46029 | C9: =21000+21000+45000+21000+338000+21000+21000 -> 488000 | D9: =20524000 -> 20524000 | F9: =SUM('KEFA 2026'!$C9:$E9) -> 21012000
A10: 46030 | B10: 46030 | C10: =2010000+21000+21000+21000 -> 2073000 | F10: =SUM('KEFA 2026'!$C10:$E10) -> 2073000
A11: 46031 | B11: 46031 | C11: =26000+26000+115000+21000+62000+212000+21000 -> 483000 | D11: =8332000 -> 8332000 | E11: =145000+21000 -> 166000 | F11: =SUM('KEFA 2026'!$C11:$E11) -> 8981000
A12: 46032 | B12: 46032 | C12: =21000+21000+31000+21000+41000+21000 -> 156000 | F12: =SUM('KEFA 2026'!$C12:$E12) -> 156000
A13: 46033 | B13: 46033 | C13: =21000+131000+21000 -> 173000 | E13: =1450000 -> 1450000 | F13: =SUM('KEFA 2026'!$C13:$E13) -> 1623000
A14: 46034 | B14: 46034 | C14: =21000 -> 21000 | D14: =10744000 -> 10744000 | F14: =SUM('KEFA 2026'!$C14:$E14) -> 10765000
A15: 46035 | B15: 46035 | C15: =21000+101000+41000+42000+21000+475000+21000+44000+191000 -> 957000 | D15: =37000+214000 -> 251000 | F15: =SUM('KEFA 2026'!$C15:$E15) -> 1208000
A16: 46036 | B16: 46036 | C16: =21000+21000+41000+379000+999000+21000+41000+145000 -> 1668000 | D16: =8023000 -> 8023000 | F16: =SUM('KEFA 2026'!$C16:$E16) -> 9691000
A17: 46037 | B17: 46037 | C17: =42000+21000+230000+21000+42000+145000 -> 501000 | D17: =5157000+21000 -> 5178000 | E17: =21000 -> 21000 | F17: =SUM('KEFA 2026'!$C17:$E17) -> 5700000
A18: 46038 | B18: 46038 | C18: =21000+21000+3800000+21000+127000 -> 3990000 | F18: =SUM('KEFA 2026'!$C18:$E18) -> 3990000
A19: 46039 | B19: 46039 | C19: =257000+21000+21000+21000 -> 320000 | D19: =61000+26000 -> 87000 | F19: =SUM('KEFA 2026'!$C19:$E19) -> 407000
A20: 46040 | B20: 46040 | C20: =21000+42000+83000+21000+999000 -> 1166000 | F20: =SUM('KEFA 2026'!$C20:$E20) -> 1166000
A21: 46041 | B21: 46041 | C21: =26000+3239500+21000 -> 3286500 | D21: =9578500 -> 9578500 | F21: =SUM('KEFA 2026'!$C21:$E21) -> 12865000
A22: 46042 | B22: 46042 | C22: =21000+41000+42000+21000+21000 -> 146000 | F22: =SUM('KEFA 2026'!$C22:$E22) -> 146000
A23: 46043 | B23: 46043 | C23: =21000+26000+61000 -> 108000 | D23: =10859000 -> 10859000 | E23: =21000 -> 21000 | F23: =SUM('KEFA 2026'!$C23:$E23) -> 10988000
A24: 46044 | B24: 46044 | C24: =21000+21000+21000+21000+301000+21000+21000 -> 427000 | F24: =SUM('KEFA 2026'!$C24:$E24) -> 427000
A25: 46045 | B25: 46045 | C25: =21000+21000+21000+26000+42000+21000+44000+244000 -> 440000 | D25: =5322000+41000 -> 5363000 | F25: =SUM('KEFA 2026'!$C25:$E25) -> 5803000
A26: 46046 | B26: 46046 | C26: =21000+31000+26000 -> 78000 | D26: =249000+21000+515556 -> 785556 | F26: =SUM('KEFA 2026'!$C26:$E26) -> 863556
A27: 46047 | B27: 46047 | C27: =21000+21000+1400000+21000+21000+21000+46000 -> 1551000 | F27: =SUM('KEFA 2026'!$C27:$E27) -> 1551000
A28: 46048 | B28: 46048 | C28: =52000+21000+21000+21000 -> 115000 | D28: =11599000 -> 11599000 | F28: =SUM('KEFA 2026'!$C28:$E28) -> 11714000
A29: 46049 | B29: 46049 | C29: =21000+21000+21000+379000+21000+21000+21000 -> 505000 | E29: =21000 -> 21000 | F29: =SUM('KEFA 2026'!$C29:$E29) -> 526000
A30: 46050 | B30: 46050 | C30: =21000+2268884+49000+42000+1134442+1134442+21000+21000+300600+39000 -> 5031368 | D30: =9081500 -> 9081500 | E30: =21000 -> 21000 | F30: =SUM('KEFA 2026'!$C30:$E30) -> 14133868
A31: 46051 | B31: 46051 | C31: =21000+21000+21000+21000+99000+42000+240000+21000 -> 486000 | F31: =SUM('KEFA 2026'!$C31:$E31) -> 486000
A32: 46052 | B32: 46052 | C32: =21000+21000+1100000+41000+21000+76000 -> 1280000 | D32: =3959500 -> 3959500 | E32: =21000 -> 21000 | F32: =SUM('KEFA 2026'!$C32:$E32) -> 5260500
A33: 46053 | B33: 46053 | C33: =41000+21000+21000+1400000+21000 -> 1504000 | E33: =42000 -> 42000 | F33: =SUM('KEFA 2026'!$C33:$E33) -> 1546000
A34: 46054 | B34: 46054 | C34: =22000 -> 22000 | F34: =SUM('KEFA 2026'!$C34:$E34) -> 22000
A35: 46055 | B35: 46055 | C35: =26000+26000+205000 -> 257000 | D35: =11580000 -> 11580000 | F35: =SUM('KEFA 2026'!$C35:$E35) -> 11837000
A36: 46056 | B36: 46056 | C36: =21000+21000+42000+63000+21000 -> 168000 | F36: =SUM('KEFA 2026'!$C36:$E36) -> 168000
A37: 46057 | B37: 46057 | C37: =21000+21000+62000+21000 -> 125000 | D37: =8512500+100000 -> 8612500 | F37: =SUM('KEFA 2026'!$C37:$E37) -> 8737500
A38: 46058 | B38: 46058 | C38: =97000+21000+21000+21000+21000+21000+41000+21000 -> 264000 | F38: =SUM('KEFA 2026'!$C38:$E38) -> 264000
A39: 46059 | B39: 46059 | C39: =26000+21000+21000+200000+21000+200000+41000+21000+21000+41000+42000 -> 655000 | D39: =6070000 -> 6070000 | F39: =SUM('KEFA 2026'!$C39:$E39) -> 6725000
A40: 46060 | B40: 46060 | C40: =62000+41000+21000+21000+87000+21000+41000 -> 294000 | E40: =21000 -> 21000 | F40: =SUM('KEFA 2026'!$C40:$E40) -> 315000
...

Sheet NIKI NIKI 2026
A1: TOTAL | C1: SETORAN BANK | F1: =SUBTOTAL(9,F3:F424) -> 32164388
A2: Hari | B2: Tanggal | C2: BRI | D2: BNI | E2: LAINNYA | F2: TOTAL SETORAN
A3: 46023 | B3: 46023 | F3: =SUM('NIKI NIKI 2026'!$C3:$E3) -> 0
A4: 46024 | B4: 46024 | F4: =SUM('NIKI NIKI 2026'!$C4:$E4) -> 0
A5: 46025 | B5: 46025 | F5: =SUM('NIKI NIKI 2026'!$C5:$E5) -> 0
A6: 46026 | B6: 46026 | F6: =SUM('NIKI NIKI 2026'!$C6:$E6) -> 0
A7: 46027 | B7: 46027 | C7: =3656000 -> 3656000 | F7: =SUM('NIKI NIKI 2026'!$C7:$E7) -> 3656000
A8: 46028 | B8: 46028 | F8: =SUM('NIKI NIKI 2026'!$C8:$E8) -> 0
A9: 46029 | B9: 46029 | F9: =SUM('NIKI NIKI 2026'!$C9:$E9) -> 0
A10: 46030 | B10: 46030 | F10: =SUM('NIKI NIKI 2026'!$C10:$E10) -> 0
A11: 46031 | B11: 46031 | F11: =SUM('NIKI NIKI 2026'!$C11:$E11) -> 0
A12: 46032 | B12: 46032 | F12: =SUM('NIKI NIKI 2026'!$C12:$E12) -> 0
A13: 46033 | B13: 46033 | F13: =SUM('NIKI NIKI 2026'!$C13:$E13) -> 0
A14: 46034 | B14: 46034 | F14: =SUM('NIKI NIKI 2026'!$C14:$E14) -> 0
A15: 46035 | B15: 46035 | C15: =5204500 -> 5204500 | F15: =SUM('NIKI NIKI 2026'!$C15:$E15) -> 5204500
A16: 46036 | B16: 46036 | F16: =SUM('NIKI NIKI 2026'!$C16:$E16) -> 0
A17: 46037 | B17: 46037 | C17: =2512000 -> 2512000 | F17: =SUM('NIKI NIKI 2026'!$C17:$E17) -> 2512000
A18: 46038 | B18: 46038 | F18: =SUM('NIKI NIKI 2026'!$C18:$E18) -> 0
A19: 46039 | B19: 46039 | F19: =SUM('NIKI NIKI 2026'!$C19:$E19) -> 0
A20: 46040 | B20: 46040 | F20: =SUM('NIKI NIKI 2026'!$C20:$E20) -> 0
A21: 46041 | B21: 46041 | F21: =SUM('NIKI NIKI 2026'!$C21:$E21) -> 0
A22: 46042 | B22: 46042 | F22: =SUM('NIKI NIKI 2026'!$C22:$E22) -> 0
A23: 46043 | B23: 46043 | C23: =3357000 -> 3357000 | F23: =SUM('NIKI NIKI 2026'!$C23:$E23) -> 3357000
A24: 46044 | B24: 46044 | F24: =SUM('NIKI NIKI 2026'!$C24:$E24) -> 0
A25: 46045 | B25: 46045 | F25: =SUM('NIKI NIKI 2026'!$C25:$E25) -> 0
A26: 46046 | B26: 46046 | F26: =SUM('NIKI NIKI 2026'!$C26:$E26) -> 0
A27: 46047 | B27: 46047 | F27: =SUM('NIKI NIKI 2026'!$C27:$E27) -> 0
A28: 46048 | B28: 46048 | F28: =SUM('NIKI NIKI 2026'!$C28:$E28) -> 0
A29: 46049 | B29: 46049 | F29: =SUM('NIKI NIKI 2026'!$C29:$E29) -> 0
A30: 46050 | B30: 46050 | E30: =1787500 -> 1787500 | F30: =SUM('NIKI NIKI 2026'!$C30:$E30) -> 1787500
A31: 46051 | B31: 46051 | D31: =77000 -> 77000 | F31: =SUM('NIKI NIKI 2026'!$C31:$E31) -> 77000
A32: 46052 | B32: 46052 | F32: =SUM('NIKI NIKI 2026'!$C32:$E32) -> 0
A33: 46053 | B33: 46053 | F33: =SUM('NIKI NIKI 2026'!$C33:$E33) -> 0
A34: 46054 | B34: 46054 | F34: =SUM('NIKI NIKI 2026'!$C34:$E34) -> 0
A35: 46055 | B35: 46055 | C35: =21000 -> 21000 | E35: =3968000 -> 3968000 | F35: =SUM('NIKI NIKI 2026'!$C35:$E35) -> 3989000
A36: 46056 | B36: 46056 | F36: =SUM('NIKI NIKI 2026'!$C36:$E36) -> 0
A37: 46057 | B37: 46057 | F37: =SUM('NIKI NIKI 2026'!$C37:$E37) -> 0
A38: 46058 | B38: 46058 | F38: =SUM('NIKI NIKI 2026'!$C38:$E38) -> 0
A39: 46059 | B39: 46059 | C39: =1851000 -> 1851000 | D39: =535288 -> 535288 | F39: =SUM('NIKI NIKI 2026'!$C39:$E39) -> 2386288
A40: 46060 | B40: 46060 | F40: =SUM('NIKI NIKI 2026'!$C40:$E40) -> 0
...

Sheet OESAO 2026
A1: TOTAL | C1: SETORAN BANK | F1: =SUBTOTAL(9,F3:F419) -> 105618820
A2: Hari | B2: Tanggal | C2: BRI | D2: BNI | E2: LAINNYA | F2: TOTAL SETORAN
A3: 46023 | B3: 46023 | F3: =SUM('OESAO 2026'!$C3:$E3) -> 0
A4: 46024 | B4: 46024 | E4: =546000 -> 546000 | F4: =SUM('OESAO 2026'!$C4:$E4) -> 546000
A5: 46025 | B5: 46025 | C5: =107000+21000+61000+419000 -> 608000 | F5: =SUM('OESAO 2026'!$C5:$E5) -> 608000
A6: 46026 | B6: 46026 | F6: =SUM('OESAO 2026'!$C6:$E6) -> 0
A7: 46027 | B7: 46027 | C7: =238580+21000 -> 259580 | D7: =6532000+23000 -> 6555000 | F7: =SUM('OESAO 2026'!$C7:$E7) -> 6814580
A8: 46028 | B8: 46028 | C8: =544931 -> 544931 | D8: =464800+1757000 -> 2221800 | F8: =SUM('OESAO 2026'!$C8:$E8) -> 2766731
A9: 46029 | B9: 46029 | C9: =21000+352000+193000 -> 566000 | D9: =1630150+21000+267000+21000 -> 1939150 | F9: =SUM('OESAO 2026'!$C9:$E9) -> 2505150
A10: 46030 | B10: 46030 | C10: =1241000+25000 -> 1266000 | D10: =213825+51000 -> 264825 | F10: =SUM('OESAO 2026'!$C10:$E10) -> 1530825
A11: 46031 | B11: 46031 | C11: =317000 -> 317000 | D11: =943925+667600+400000 -> 2011525 | F11: =SUM('OESAO 2026'!$C11:$E11) -> 2328525
A12: 46032 | B12: 46032 | D12: =2151900 -> 2151900 | E12: =177000 -> 177000 | F12: =SUM('OESAO 2026'!$C12:$E12) -> 2328900
A13: 46033 | B13: 46033 | E13: =40000 -> 40000 | F13: =SUM('OESAO 2026'!$C13:$E13) -> 40000
A14: 46034 | B14: 46034 | C14: =257000+471000+21000 -> 749000 | D14: =495995 -> 495995 | E14: =500000 -> 500000 | F14: =SUM('OESAO 2026'!$C14:$E14) -> 1744995
A15: 46035 | B15: 46035 | C15: =1974000+26000 -> 2000000 | D15: =1051000+329846+21000 -> 1401846 | F15: =SUM('OESAO 2026'!$C15:$E15) -> 3401846
A16: 46036 | B16: 46036 | C16: =726325 -> 726325 | D16: =2233+216000+42000 -> 260233 | E16: =1211640 -> 1211640 | F16: =SUM('OESAO 2026'!$C16:$E16) -> 2198198
A17: 46037 | B17: 46037 | C17: =140700+841000+116000 -> 1097700 | D17: =1285550+1183770 -> 2469320 | F17: =SUM('OESAO 2026'!$C17:$E17) -> 3567020
A18: 46038 | B18: 46038 | C18: =21000 -> 21000 | D18: =25000 -> 25000 | F18: =SUM('OESAO 2026'!$C18:$E18) -> 46000
A19: 46039 | B19: 46039 | C19: =589692 -> 589692 | D19: =3565000+21000 -> 3586000 | F19: =SUM('OESAO 2026'!$C19:$E19) -> 4175692
A20: 46040 | B20: 46040 | C20: =21000 -> 21000 | D20: =21000 -> 21000 | E20: =21000 -> 21000 | F20: =SUM('OESAO 2026'!$C20:$E20) -> 63000
A21: 46041 | B21: 46041 | C21: =670400+50000 -> 720400 | D21: =1659917+1183770 -> 2843687 | F21: =SUM('OESAO 2026'!$C21:$E21) -> 3564087
A22: 46042 | B22: 46042 | C22: =1365000+26000 -> 1391000 | D22: =1085037+44000+21000+216000+50000 -> 1416037 | F22: =SUM('OESAO 2026'!$C22:$E22) -> 2807037
A23: 46043 | B23: 46043 | D23: =2104000+21000+21000+41000+21000 -> 2208000 | F23: =SUM('OESAO 2026'!$C23:$E23) -> 2208000
A24: 46044 | B24: 46044 | C24: =218000 -> 218000 | D24: =3028370+50000 -> 3078370 | F24: =SUM('OESAO 2026'!$C24:$E24) -> 3296370
A25: 46045 | B25: 46045 | D25: =1539550+21000 -> 1560550 | F25: =SUM('OESAO 2026'!$C25:$E25) -> 1560550
A26: 46046 | B26: 46046 | C26: =644275+35000+485000+456000 -> 1620275 | D26: =936000 -> 936000 | E26: =45000 -> 45000 | F26: =SUM('OESAO 2026'!$C26:$E26) -> 2601275
A27: 46047 | B27: 46047 | F27: =SUM('OESAO 2026'!$C27:$E27) -> 0
A28: 46048 | B28: 46048 | C28: =284900 -> 284900 | D28: =2253775 -> 2253775 | F28: =SUM('OESAO 2026'!$C28:$E28) -> 2538675
A29: 46049 | B29: 46049 | C29: =295000 -> 295000 | D29: =1201075+21000+21000+76000 -> 1319075 | F29: =SUM('OESAO 2026'!$C29:$E29) -> 1614075
A30: 46050 | B30: 46050 | D30: =684000 -> 684000 | F30: =SUM('OESAO 2026'!$C30:$E30) -> 684000
A31: 46051 | B31: 46051 | C31: =364000 -> 364000 | D31: =1957000+51000 -> 2008000 | E31: =355000 -> 355000 | F31: =SUM('OESAO 2026'!$C31:$E31) -> 2727000
A32: 46052 | B32: 46052 | C32: =21000+44000 -> 65000 | D32: =2045963 -> 2045963 | F32: =SUM('OESAO 2026'!$C32:$E32) -> 2110963
A33: 46053 | B33: 46053 | C33: =42000+21000 -> 63000 | D33: =2295220 -> 2295220 | F33: =SUM('OESAO 2026'!$C33:$E33) -> 2358220
A34: 46054 | B34: 46054 | C34: =21000 -> 21000 | F34: =SUM('OESAO 2026'!$C34:$E34) -> 21000
A35: 46055 | B35: 46055 | D35: =1444725 -> 1444725 | F35: =SUM('OESAO 2026'!$C35:$E35) -> 1444725
A36: 46056 | B36: 46056 | C36: =333731+1715000+222000 -> 2270731 | D36: =2617906+25000 -> 2642906 | F36: =SUM('OESAO 2026'!$C36:$E36) -> 4913637
A37: 46057 | B37: 46057 | D37: =731000+42000+619250 -> 1392250 | F37: =SUM('OESAO 2026'!$C37:$E37) -> 1392250
A38: 46058 | B38: 46058 | D38: =2426802+21000+25000 -> 2472802 | F38: =SUM('OESAO 2026'!$C38:$E38) -> 2472802
A39: 46059 | B39: 46059 | C39: =21000 -> 21000 | D39: =329000+21000 -> 350000 | F39: =SUM('OESAO 2026'!$C39:$E39) -> 371000
A40: 46060 | B40: 46060 | C40: =1406820+21000+556825+21000 -> 2005645 | D40: =21000+63000 -> 84000 | F40: =SUM('OESAO 2026'!$C40:$E40) -> 2089645
...

Sheet ROTE 2026
A1: TOTAL | C1: SETORAN BANK | F1: =SUBTOTAL(9,F3:F400) -> 219774440
A2: Hari | B2: Tanggal | C2: BRI | D2: BNI | E2: LAINNYA | F2: TOTAL SETORAN
A3: 46023 | B3: 46023 | F3: =SUM('ROTE 2026'!$C3:$E3) -> 0
A4: 46024 | B4: 46024 | C4: =189000+41000+26000+97000 -> 353000 | D4: =1941000+15000 -> 1956000 | E4: =172252+41000 -> 213252 | F4: =SUM('ROTE 2026'!$C4:$E4) -> 2522252
A5: 46025 | B5: 46025 | C5: =26000+413500+243000+26000+26000 -> 734500 | D5: =21000+135000+20000 -> 176000 | E5: =101000 -> 101000 | F5: =SUM('ROTE 2026'!$C5:$E5) -> 1011500
A6: 46026 | B6: 46026 | F6: =SUM('ROTE 2026'!$C6:$E6) -> 0
A7: 46027 | B7: 46027 | C7: =136300+999000+255000+71000+26000+145000+643000+191000+26000 -> 2492300 | D7: =8156000+240000+20000+135000 -> 8551000 | F7: =SUM('ROTE 2026'!$C7:$E7) -> 11043300
A8: 46028 | B8: 46028 | C8: =26000+21000 -> 47000 | D8: =7853000+850000+40000+200000+51000+50000 -> 9044000 | E8: =182500+26000+969000 -> 1177500 | F8: =SUM('ROTE 2026'!$C8:$E8) -> 10268500
A9: 46029 | B9: 46029 | C9: =210000+50000+41000+41000+130000+21000 -> 493000 | D9: =4502500+21000+250000+31000+50000+50000+21000+151000 -> 5076500 | E9: =21000+21000 -> 42000 | F9: =SUM('ROTE 2026'!$C9:$E9) -> 5611500
A10: 46030 | B10: 46030 | C10: =180900+26000+270000+26000+26000+150000+21000+41000+25000+21000 -> 786900 | D10: =4348500+126000+26000+45000+85000+100000+36000+200000+190000+474000 -> 5630500 | F10: =SUM('ROTE 2026'!$C10:$E10) -> 6417400
A11: 46031 | B11: 46031 | C11: =26000+16000+26000+26000+26000+41000+21000+21000 -> 203000 | D11: =26000+6125500+100000+21000+76000+10000+21000 -> 6379500 | E11: =26000+36000 -> 62000 | F11: =SUM('ROTE 2026'!$C11:$E11) -> 6644500
A12: 46032 | B12: 46032 | C12: =41000+51000+26000+41000 -> 159000 | D12: =26000+21000+500000+45000+100000+50000+16000 -> 758000 | F12: =SUM('ROTE 2026'!$C12:$E12) -> 917000
A13: 46033 | B13: 46033 | C13: =364625+45000 -> 409625 | D13: =51000+182310+26000+26000+75000 -> 360310 | F13: =SUM('ROTE 2026'!$C13:$E13) -> 769935
A14: 46034 | B14: 46034 | D14: =7071500 -> 7071500 | F14: =SUM('ROTE 2026'!$C14:$E14) -> 7071500
A15: 46035 | B15: 46035 | C15: =26000+42000+26000+215000+460000 -> 769000 | D15: =242000+21000+350000+10000+26000+15000 -> 664000 | E15: =97000+26000 -> 123000 | F15: =SUM('ROTE 2026'!$C15:$E15) -> 1556000
A16: 46036 | B16: 46036 | C16: =51000+21000+36000+42000 -> 150000 | D16: =4596000+21000+20000+98000+100000 -> 4835000 | E16: =21000 -> 21000 | F16: =SUM('ROTE 2026'!$C16:$E16) -> 5006000
A17: 46037 | B17: 46037 | C17: =21000+21000+21000+101000+21000+30000+21000 -> 236000 | D17: =1625000+52000+26000+175000+20000+26000 -> 1924000 | E17: =21000 -> 21000 | F17: =SUM('ROTE 2026'!$C17:$E17) -> 2181000
A18: 46038 | B18: 46038 | C18: =21000+26000+26000+150000+20000+21000 -> 264000 | D18: =21000+200000+135000+700000+50000 -> 1106000 | F18: =SUM('ROTE 2026'!$C18:$E18) -> 1370000
A19: 46039 | B19: 46039 | C19: =42000+62000+41000+52000 -> 197000 | D19: =21000+26000+26000+21000+625000+100000 -> 819000 | E19: =26000+21000+364625 -> 411625 | F19: =SUM('ROTE 2026'!$C19:$E19) -> 1427625
A20: 46040 | B20: 46040 | C20: =925000 -> 925000 | F20: =SUM('ROTE 2026'!$C20:$E20) -> 925000
A21: 46041 | B21: 46041 | C21: =26000+26000+26000+26000+21000+26000+26000+21000+61000 -> 259000 | D21: =13092000+200000+330500+51000 -> 13673500 | E21: =21000 -> 21000 | F21: =SUM('ROTE 2026'!$C21:$E21) -> 13953500
A22: 46042 | B22: 46042 | D22: =6509500+10000+120000 -> 6639500 | F22: =SUM('ROTE 2026'!$C22:$E22) -> 6639500
A23: 46043 | B23: 46043 | D23: =1321000 -> 1321000 | F23: =SUM('ROTE 2026'!$C23:$E23) -> 1321000
A24: 46044 | B24: 46044 | D24: =41000+100000 -> 141000 | F24: =SUM('ROTE 2026'!$C24:$E24) -> 141000
A25: 46045 | B25: 46045 | C25: =26000 -> 26000 | D25: =166000+11000 -> 177000 | F25: =SUM('ROTE 2026'!$C25:$E25) -> 203000
A26: 46046 | B26: 46046 | F26: =SUM('ROTE 2026'!$C26:$E26) -> 0
A27: 46047 | B27: 46047 | F27: =SUM('ROTE 2026'!$C27:$E27) -> 0
A28: 46048 | B28: 46048 | D28: =11000 -> 11000 | F28: =SUM('ROTE 2026'!$C28:$E28) -> 11000
A29: 46049 | B29: 46049 | F29: =SUM('ROTE 2026'!$C29:$E29) -> 0
A30: 46050 | B30: 46050 | D30: =1795000 -> 1795000 | F30: =SUM('ROTE 2026'!$C30:$E30) -> 1795000
A31: 46051 | B31: 46051 | C31: =113000+21000+87000+25000+26000+26000+390000+84000+21000+51000+21000+51000+41000+354000+26000+21000+25000+62000+316000+161000+84000+42000+21000+21000 -> 2090000 | D31: =78000+21000+127000+61000+130000+125000+26000+52000+203000+101000+21000+61000+83000+41000+350000+485000+260000 -> 2225000 | E31: =87000+21000+42000 -> 150000 | F31: =SUM('ROTE 2026'!$C31:$E31) -> 4465000
A32: 46052 | B32: 46052 | C32: =61000+40000+26000+26000+51000+42000+258000 -> 504000 | D32: =17333500+52000+26000+32000+21000+30000+195000 -> 17689500 | E32: =21000 -> 21000 | F32: =SUM('ROTE 2026'!$C32:$E32) -> 18214500
A33: 46053 | B33: 46053 | C33: =21000+76000+227000+26000+329000+26000+21000+21000+41000+51000+26000 -> 865000 | D33: =21000+21000+21000+21000+135000+271000+200000+51000 -> 741000 | E33: =42000+286000+331000 -> 659000 | F33: =SUM('ROTE 2026'!$C33:$E33) -> 2265000
A34: 46054 | B34: 46054 | C34: =21000+101000+20000+151000+21000 -> 314000 | F34: =SUM('ROTE 2026'!$C34:$E34) -> 314000
A35: 46055 | B35: 46055 | D35: =8455500+495000 -> 8950500 | F35: =SUM('ROTE 2026'!$C35:$E35) -> 8950500
A36: 46056 | B36: 46056 | C36: =21000+26000+21000+41000+50000+21000+21000+124000+42000+42000 -> 409000 | D36: =977000+193000+217000+21000+61000+26000+26000+26000 -> 1547000 | E36: =50000 -> 50000 | F36: =SUM('ROTE 2026'!$C36:$E36) -> 2006000
A37: 46057 | B37: 46057 | C37: =21000+26000+52000+26000+21000+26000 -> 172000 | D37: =4226000+130000+26000+21000+150000+21000 -> 4574000 | E37: =41000+26000 -> 67000 | F37: =SUM('ROTE 2026'!$C37:$E37) -> 4813000
A38: 46058 | B38: 46058 | C38: =42000+31000+26000+26000+21000+999999+20000+139000 -> 1304999 | D38: =3469000+26000+77000+26000+45000+26000+21000 -> 3690000 | E38: =21000+21000+61000+21000 -> 124000 | F38: =SUM('ROTE 2026'!$C38:$E38) -> 5118999
A39: 46059 | B39: 46059 | C39: =21000 -> 21000 | D39: =3375500+100000+51000+20000+47000+50000 -> 3643500 | E39: =121000 -> 121000 | F39: =SUM('ROTE 2026'!$C39:$E39) -> 3785500
A40: 46060 | B40: 46060 | C40: =21000+21000 -> 42000 | E40: =865000+21000 -> 886000 | F40: =SUM('ROTE 2026'!$C40:$E40) -> 928000
...

Sheet SABU 2026
A1: TOTAL | C1: SETORAN BANK | F1: =SUBTOTAL(9,F3:F395) -> 194060678
A2: Hari | B2: Tanggal | C2: BRI | D2: BNI | E2: LAINNYA | F2: TOTAL SETORAN
A3: 46023 | B3: 46023 | F3: =SUM('SABU 2026'!$C3:$E3) -> 0
A4: 46024 | B4: 46024 | F4: =SUM('SABU 2026'!$C4:$E4) -> 0
A5: 46025 | B5: 46025 | C5: =77000+550000+26000+26000+100000+44000+26000+285700 -> 1134700 | F5: =SUM('SABU 2026'!$C5:$E5) -> 1134700
A6: 46026 | B6: 46026 | C6: =264000+71000+358200+590000 -> 1283200 | F6: =SUM('SABU 2026'!$C6:$E6) -> 1283200
A7: 46027 | B7: 46027 | C7: =186000 -> 186000 | F7: =SUM('SABU 2026'!$C7:$E7) -> 186000
A8: 46028 | B8: 46028 | C8: =11956871+1872060+591087+320000+26000+101000+5091599 -> 19958617 | F8: =SUM('SABU 2026'!$C8:$E8) -> 19958617
A9: 46029 | B9: 46029 | C9: =1287800+175000+3261900+590013 -> 5314713 | F9: =SUM('SABU 2026'!$C9:$E9) -> 5314713
A10: 46030 | B10: 46030 | C10: =350000+26000+52000+26000 -> 454000 | F10: =SUM('SABU 2026'!$C10:$E10) -> 454000
A11: 46031 | B11: 46031 | C11: =1709394+6966306+300000+621000 -> 9596700 | F11: =SUM('SABU 2026'!$C11:$E11) -> 9596700
A12: 46032 | B12: 46032 | C12: =202709+26000+51000+690000+178000 -> 1147709 | F12: =SUM('SABU 2026'!$C12:$E12) -> 1147709
A13: 46033 | B13: 46033 | F13: =SUM('SABU 2026'!$C13:$E13) -> 0
A14: 46034 | B14: 46034 | C14: =1745353+6432091+795058+860300 -> 9832802 | F14: =SUM('SABU 2026'!$C14:$E14) -> 9832802
A15: 46035 | B15: 46035 | C15: =26000+76000+26000 -> 128000 | F15: =SUM('SABU 2026'!$C15:$E15) -> 128000
A16: 46036 | B16: 46036 | C16: =4220200 -> 4220200 | F16: =SUM('SABU 2026'!$C16:$E16) -> 4220200
A17: 46037 | B17: 46037 | C17: =34000+76000+52000+26000+89000 -> 277000 | F17: =SUM('SABU 2026'!$C17:$E17) -> 277000
A18: 46038 | B18: 46038 | F18: =SUM('SABU 2026'!$C18:$E18) -> 0
A19: 46039 | B19: 46039 | C19: =78000+235000+26000+26000+26000 -> 391000 | F19: =SUM('SABU 2026'!$C19:$E19) -> 391000
A20: 46040 | B20: 46040 | F20: =SUM('SABU 2026'!$C20:$E20) -> 0
A21: 46041 | B21: 46041 | C21: =4648769+1628071+5850488+214000+11161657+494000 -> 23996985 | F21: =SUM('SABU 2026'!$C21:$E21) -> 23996985
A22: 46042 | B22: 46042 | C22: =128000 -> 128000 | F22: =SUM('SABU 2026'!$C22:$E22) -> 128000
A23: 46043 | B23: 46043 | F23: =SUM('SABU 2026'!$C23:$E23) -> 0
A24: 46044 | B24: 46044 | F24: =SUM('SABU 2026'!$C24:$E24) -> 0
A25: 46045 | B25: 46045 | F25: =SUM('SABU 2026'!$C25:$E25) -> 0
A26: 46046 | B26: 46046 | F26: =SUM('SABU 2026'!$C26:$E26) -> 0
A27: 46047 | B27: 46047 | F27: =SUM('SABU 2026'!$C27:$E27) -> 0
A28: 46048 | B28: 46048 | F28: =SUM('SABU 2026'!$C28:$E28) -> 0
A29: 46049 | B29: 46049 | F29: =SUM('SABU 2026'!$C29:$E29) -> 0
A30: 46050 | B30: 46050 | F30: =SUM('SABU 2026'!$C30:$E30) -> 0
A31: 46051 | B31: 46051 | F31: =SUM('SABU 2026'!$C31:$E31) -> 0
A32: 46052 | B32: 46052 | F32: =SUM('SABU 2026'!$C32:$E32) -> 0
A33: 46053 | B33: 46053 | C33: =34000+128000+127000+52000+325000+51000+77000+76000+26000+44000+26000+26000+55000+100000 -> 1147000 | F33: =SUM('SABU 2026'!$C33:$E33) -> 1147000
A34: 46054 | B34: 46054 | C34: =136000+102000+222000+277000+61000+190000+26000+26000+26000 -> 1066000 | F34: =SUM('SABU 2026'!$C34:$E34) -> 1066000
A35: 46055 | B35: 46055 | C35: =10498958+10273330+99000+125000+115000 -> 21111288 | F35: =SUM('SABU 2026'!$C35:$E35) -> 21111288
A36: 46056 | B36: 46056 | C36: =392000+26000+26000 -> 444000 | F36: =SUM('SABU 2026'!$C36:$E36) -> 444000
A37: 46057 | B37: 46057 | F37: =SUM('SABU 2026'!$C37:$E37) -> 0
A38: 46058 | B38: 46058 | C38: =6564963+9981935+765413+26000+4808412 -> 22146723 | F38: =SUM('SABU 2026'!$C38:$E38) -> 22146723
A39: 46059 | B39: 46059 | C39: =68000 -> 68000 | F39: =SUM('SABU 2026'!$C39:$E39) -> 68000
A40: 46060 | B40: 46060 | C40: =1345000+369600+149068+52000+26000+44000+1282475 -> 3268143 | F40: =SUM('SABU 2026'!$C40:$E40) -> 3268143
...

Sheet SEMAU 2026
A1: TOTAL | C1: SETORAN BANK | F1: =SUBTOTAL(9,F3:F414) -> 3575200
A2: Hari | B2: Tanggal | C2: BRI | D2: BNI | E2: LAINNYA | F2: TOTAL SETORAN
A3: 46023 | B3: 46023 | F3: =SUM('SEMAU 2026'!$C3:$E3) -> 0
A4: 46024 | B4: 46024 | C4: =101000 -> 101000 | F4: =SUM('SEMAU 2026'!$C4:$E4) -> 101000
A5: 46025 | B5: 46025 | F5: =SUM('SEMAU 2026'!$C5:$E5) -> 0
A6: 46026 | B6: 46026 | F6: =SUM('SEMAU 2026'!$C6:$E6) -> 0
A7: 46027 | B7: 46027 | F7: =SUM('SEMAU 2026'!$C7:$E7) -> 0
A8: 46028 | B8: 46028 | F8: =SUM('SEMAU 2026'!$C8:$E8) -> 0
A9: 46029 | B9: 46029 | E9: =423000 -> 423000 | F9: =SUM('SEMAU 2026'!$C9:$E9) -> 423000
A10: 46030 | B10: 46030 | F10: =SUM('SEMAU 2026'!$C10:$E10) -> 0
A11: 46031 | B11: 46031 | C11: =856000 -> 856000 | F11: =SUM('SEMAU 2026'!$C11:$E11) -> 856000
A12: 46032 | B12: 46032 | F12: =SUM('SEMAU 2026'!$C12:$E12) -> 0
A13: 46033 | B13: 46033 | F13: =SUM('SEMAU 2026'!$C13:$E13) -> 0
A14: 46034 | B14: 46034 | F14: =SUM('SEMAU 2026'!$C14:$E14) -> 0
A15: 46035 | B15: 46035 | F15: =SUM('SEMAU 2026'!$C15:$E15) -> 0
A16: 46036 | B16: 46036 | F16: =SUM('SEMAU 2026'!$C16:$E16) -> 0
A17: 46037 | B17: 46037 | F17: =SUM('SEMAU 2026'!$C17:$E17) -> 0
A18: 46038 | B18: 46038 | F18: =SUM('SEMAU 2026'!$C18:$E18) -> 0
A19: 46039 | B19: 46039 | F19: =SUM('SEMAU 2026'!$C19:$E19) -> 0
A20: 46040 | B20: 46040 | F20: =SUM('SEMAU 2026'!$C20:$E20) -> 0
A21: 46041 | B21: 46041 | F21: =SUM('SEMAU 2026'!$C21:$E21) -> 0
A22: 46042 | B22: 46042 | F22: =SUM('SEMAU 2026'!$C22:$E22) -> 0
A23: 46043 | B23: 46043 | E23: =558000 -> 558000 | F23: =SUM('SEMAU 2026'!$C23:$E23) -> 558000
A24: 46044 | B24: 46044 | F24: =SUM('SEMAU 2026'!$C24:$E24) -> 0
A25: 46045 | B25: 46045 | F25: =SUM('SEMAU 2026'!$C25:$E25) -> 0
A26: 46046 | B26: 46046 | F26: =SUM('SEMAU 2026'!$C26:$E26) -> 0
A27: 46047 | B27: 46047 | F27: =SUM('SEMAU 2026'!$C27:$E27) -> 0
A28: 46048 | B28: 46048 | F28: =SUM('SEMAU 2026'!$C28:$E28) -> 0
A29: 46049 | B29: 46049 | F29: =SUM('SEMAU 2026'!$C29:$E29) -> 0
A30: 46050 | B30: 46050 | F30: =SUM('SEMAU 2026'!$C30:$E30) -> 0
A31: 46051 | B31: 46051 | F31: =SUM('SEMAU 2026'!$C31:$E31) -> 0
A32: 46052 | B32: 46052 | F32: =SUM('SEMAU 2026'!$C32:$E32) -> 0
A33: 46053 | B33: 46053 | F33: =SUM('SEMAU 2026'!$C33:$E33) -> 0
A34: 46054 | B34: 46054 | F34: =SUM('SEMAU 2026'!$C34:$E34) -> 0
A35: 46055 | B35: 46055 | F35: =SUM('SEMAU 2026'!$C35:$E35) -> 0
A36: 46056 | B36: 46056 | E36: =322200 -> 322200 | F36: =SUM('SEMAU 2026'!$C36:$E36) -> 322200
A37: 46057 | B37: 46057 | F37: =SUM('SEMAU 2026'!$C37:$E37) -> 0
A38: 46058 | B38: 46058 | F38: =SUM('SEMAU 2026'!$C38:$E38) -> 0
A39: 46059 | B39: 46059 | F39: =SUM('SEMAU 2026'!$C39:$E39) -> 0
A40: 46060 | B40: 46060 | F40: =SUM('SEMAU 2026'!$C40:$E40) -> 0
...

Sheet SOE 2026
A1: TOTAL | C1: SETORAN BANK | F1: =SUBTOTAL(9,F3:F396) -> 173956993
A2: Hari | B2: Tanggal | C2: BRI | D2: BNI | E2: LAINNYA | F2: TOTAL SETORAN
A3: 46023 | B3: 46023 | F3: =SUM('SOE 2026'!$C3:$E3) -> 0
A4: 46024 | B4: 46024 | C4: =2000000+21000 -> 2021000 | F4: =SUM('SOE 2026'!$C4:$E4) -> 2021000
A5: 46025 | B5: 46025 | C5: =2500000+252775 -> 2752775 | F5: =SUM('SOE 2026'!$C5:$E5) -> 2752775
A6: 46026 | B6: 46026 | F6: =SUM('SOE 2026'!$C6:$E6) -> 0
A7: 46027 | B7: 46027 | C7: =21000 -> 21000 | F7: =SUM('SOE 2026'!$C7:$E7) -> 21000
A8: 46028 | B8: 46028 | C8: =10509000 -> 10509000 | D8: =250000 -> 250000 | F8: =SUM('SOE 2026'!$C8:$E8) -> 10759000
A9: 46029 | B9: 46029 | C9: =100000+229000 -> 329000 | F9: =SUM('SOE 2026'!$C9:$E9) -> 329000
A10: 46030 | B10: 46030 | C10: =39000+97000+999000+281000 -> 1416000 | F10: =SUM('SOE 2026'!$C10:$E10) -> 1416000
A11: 46031 | B11: 46031 | C11: =21000+211000+769000+289000+21000 -> 1311000 | F11: =SUM('SOE 2026'!$C11:$E11) -> 1311000
A12: 46032 | B12: 46032 | C12: =21000 -> 21000 | F12: =SUM('SOE 2026'!$C12:$E12) -> 21000
A13: 46033 | B13: 46033 | F13: =SUM('SOE 2026'!$C13:$E13) -> 0
A14: 46034 | B14: 46034 | C14: =999000+116000+229000+285000+1300000+25490500+87000+21000+21000+21000 -> 28569500 | F14: =SUM('SOE 2026'!$C14:$E14) -> 28569500
A15: 46035 | B15: 46035 | C15: =180000+97000+21000+21000+21000+21000+21000+357000+475000 -> 1214000 | D15: =100000 -> 100000 | F15: =SUM('SOE 2026'!$C15:$E15) -> 1314000
A16: 46036 | B16: 46036 | C16: =145000+100000+97000 -> 342000 | F16: =SUM('SOE 2026'!$C16:$E16) -> 342000
A17: 46037 | B17: 46037 | C17: =44000+270000+9850000 -> 10164000 | D17: =2139880 -> 2139880 | F17: =SUM('SOE 2026'!$C17:$E17) -> 12303880
A18: 46038 | B18: 46038 | C18: =21000+288000+21000+21000 -> 351000 | F18: =SUM('SOE 2026'!$C18:$E18) -> 351000
A19: 46039 | B19: 46039 | C19: =21000+163000 -> 184000 | F19: =SUM('SOE 2026'!$C19:$E19) -> 184000
A20: 46040 | B20: 46040 | F20: =SUM('SOE 2026'!$C20:$E20) -> 0
A21: 46041 | B21: 46041 | C21: =21000+21000+21000+26000+21000+39000 -> 149000 | F21: =SUM('SOE 2026'!$C21:$E21) -> 149000
A22: 46042 | B22: 46042 | C22: =388000+21000 -> 409000 | D22: =1095000 -> 1095000 | F22: =SUM('SOE 2026'!$C22:$E22) -> 1504000
A23: 46043 | B23: 46043 | C23: =13113500+61000+280350+41000+21000+21000 -> 13537850 | F23: =SUM('SOE 2026'!$C23:$E23) -> 13537850
A24: 46044 | B24: 46044 | C24: =21000+42000+83000+869000+712000+21000 -> 1748000 | F24: =SUM('SOE 2026'!$C24:$E24) -> 1748000
A25: 46045 | B25: 46045 | C25: =3366000+30000+42000 -> 3438000 | D25: =1203000+5563000 -> 6766000 | F25: =SUM('SOE 2026'!$C25:$E25) -> 10204000
A26: 46046 | B26: 46046 | C26: =21000+21000+44000 -> 86000 | F26: =SUM('SOE 2026'!$C26:$E26) -> 86000
A27: 46047 | B27: 46047 | C27: =86000 -> 86000 | D27: =21000 -> 21000 | F27: =SUM('SOE 2026'!$C27:$E27) -> 107000
A28: 46048 | B28: 46048 | C28: =21000+21000+21000+15000+83000 -> 161000 | D28: =348000 -> 348000 | F28: =SUM('SOE 2026'!$C28:$E28) -> 509000
A29: 46049 | B29: 46049 | C29: =21000+900000 -> 921000 | D29: =300000 -> 300000 | F29: =SUM('SOE 2026'!$C29:$E29) -> 1221000
A30: 46050 | B30: 46050 | C30: =20000+21000 -> 41000 | D30: =338000 -> 338000 | F30: =SUM('SOE 2026'!$C30:$E30) -> 379000
A31: 46051 | B31: 46051 | C31: =8821500+21000+41000+21000+21000+21000+21000 -> 8967500 | F31: =SUM('SOE 2026'!$C31:$E31) -> 8967500
A32: 46052 | B32: 46052 | C32: =39000+21000+21000+41000+26000+21000 -> 169000 | D32: =1230000 -> 1230000 | F32: =SUM('SOE 2026'!$C32:$E32) -> 1399000
A33: 46053 | B33: 46053 | C33: =42000+21000+21000 -> 84000 | D33: =21000 -> 21000 | F33: =SUM('SOE 2026'!$C33:$E33) -> 105000
A34: 46054 | B34: 46054 | F34: =SUM('SOE 2026'!$C34:$E34) -> 0
A35: 46055 | B35: 46055 | C35: =340000+900000+21000+31000+21000+21000 -> 1334000 | F35: =SUM('SOE 2026'!$C35:$E35) -> 1334000
A36: 46056 | B36: 46056 | C36: =5000000+257000+4167000+21000+21000+21000 -> 9487000 | F36: =SUM('SOE 2026'!$C36:$E36) -> 9487000
A37: 46057 | B37: 46057 | C37: =21000+21000 -> 42000 | D37: =400000 -> 400000 | F37: =SUM('SOE 2026'!$C37:$E37) -> 442000
A38: 46058 | B38: 46058 | C38: =44000+21000+21000 -> 86000 | D38: =42000 -> 42000 | F38: =SUM('SOE 2026'!$C38:$E38) -> 128000
A39: 46059 | B39: 46059 | C39: =21000+21000+550000+6346500 -> 6938500 | F39: =SUM('SOE 2026'!$C39:$E39) -> 6938500
A40: 46060 | B40: 46060 | C40: =82000 -> 82000 | F40: =SUM('SOE 2026'!$C40:$E40) -> 82000
...

Sheet TAMBOLAKA 2026
A1: TOTAL | C1: SETORAN BANK | F1: =SUBTOTAL(9,F3:F396) -> 183740270
A2: Hari | B2: Tanggal | C2: BRI | D2: BNI | E2: LAINNYA | F2: TOTAL SETORAN
A3: 46023 | B3: 46023 | F3: =SUM('TAMBOLAKA 2026'!$C3:$E3) -> 0
A4: 46024 | B4: 46024 | C4: =80000+200000+1290000+300000+26000 -> 1896000 | D4: =3657000+51000 -> 3708000 | F4: =SUM('TAMBOLAKA 2026'!$C4:$E4) -> 5604000
A5: 46025 | B5: 46025 | C5: =200000+57000 -> 257000 | D5: =48000+100000+5000 -> 153000 | F5: =SUM('TAMBOLAKA 2026'!$C5:$E5) -> 410000
A6: 46026 | B6: 46026 | F6: =SUM('TAMBOLAKA 2026'!$C6:$E6) -> 0
A7: 46027 | B7: 46027 | C7: =1221000 -> 1221000 | D7: =5683000+65000+150000 -> 5898000 | E7: =499490 -> 499490 | F7: =SUM('TAMBOLAKA 2026'!$C7:$E7) -> 7618490
A8: 46028 | B8: 46028 | D8: =50000+100000+173000+400000 -> 723000 | F8: =SUM('TAMBOLAKA 2026'!$C8:$E8) -> 723000
A9: 46029 | B9: 46029 | C9: =1000000 -> 1000000 | D9: =2752500 -> 2752500 | F9: =SUM('TAMBOLAKA 2026'!$C9:$E9) -> 3752500
A10: 46030 | B10: 46030 | D10: =300000+26000+743000+90000+101000+26000+26000+26000+51000+400000 -> 1789000 | F10: =SUM('TAMBOLAKA 2026'!$C10:$E10) -> 1789000
A11: 46031 | B11: 46031 | D11: =3719500+255000+51000+150000 -> 4175500 | F11: =SUM('TAMBOLAKA 2026'!$C11:$E11) -> 4175500
A12: 46032 | B12: 46032 | C12: =97000+1377000+999000+34000+26000 -> 2533000 | D12: =158000+565000+1300000+1135000+60000+500000+51000 -> 3769000 | F12: =SUM('TAMBOLAKA 2026'!$C12:$E12) -> 6302000
A13: 46033 | B13: 46033 | F13: =SUM('TAMBOLAKA 2026'!$C13:$E13) -> 0
A14: 46034 | B14: 46034 | C14: =160000+10000+261000+61000 -> 492000 | D14: =2717500+1500000+40000+26000+26000 -> 4309500 | F14: =SUM('TAMBOLAKA 2026'!$C14:$E14) -> 4801500
A15: 46035 | B15: 46035 | C15: =200000+26000+26000 -> 252000 | D15: =340000+50000 -> 390000 | F15: =SUM('TAMBOLAKA 2026'!$C15:$E15) -> 642000
A16: 46036 | B16: 46036 | C16: =30000 -> 30000 | D16: =6645000+26000+140000 -> 6811000 | F16: =SUM('TAMBOLAKA 2026'!$C16:$E16) -> 6841000
A17: 46037 | B17: 46037 | C17: =1000000+26000 -> 1026000 | D17: =303500+26000+77000 -> 406500 | F17: =SUM('TAMBOLAKA 2026'!$C17:$E17) -> 1432500
A18: 46038 | B18: 46038 | C18: =854900+200000 -> 1054900 | D18: =200000 -> 200000 | F18: =SUM('TAMBOLAKA 2026'!$C18:$E18) -> 1254900
A19: 46039 | B19: 46039 | C19: =72000+100000+26000+1463300+26000+76000+26000+51000+26000 -> 1866300 | D19: =40000+34000+26000+26000 -> 126000 | F19: =SUM('TAMBOLAKA 2026'!$C19:$E19) -> 1992300
A20: 46040 | B20: 46040 | F20: =SUM('TAMBOLAKA 2026'!$C20:$E20) -> 0
A21: 46041 | B21: 46041 | C21: =26000+51000+350000+101000+1944000+26000+300000+177000 -> 2975000 | D21: =5022000+26000+143000+236000 -> 5427000 | F21: =SUM('TAMBOLAKA 2026'!$C21:$E21) -> 8402000
A22: 46042 | B22: 46042 | C22: =26000+119000 -> 145000 | D22: =235000 -> 235000 | F22: =SUM('TAMBOLAKA 2026'!$C22:$E22) -> 380000
A23: 46043 | B23: 46043 | C23: =500000 -> 500000 | D23: =200000+79000 -> 279000 | F23: =SUM('TAMBOLAKA 2026'!$C23:$E23) -> 779000
A24: 46044 | B24: 46044 | C24: =51000+26000+197000+51000+26000+200000 -> 551000 | D24: =11555000+26000+93000+68000+31000+500000 -> 12273000 | F24: =SUM('TAMBOLAKA 2026'!$C24:$E24) -> 12824000
A25: 46045 | B25: 46045 | D25: =2414000+995000 -> 3409000 | F25: =SUM('TAMBOLAKA 2026'!$C25:$E25) -> 3409000
A26: 46046 | B26: 46046 | C26: =76000+26000+1417900 -> 1519900 | D26: =52000+478000+26000+34000 -> 590000 | F26: =SUM('TAMBOLAKA 2026'!$C26:$E26) -> 2109900
A27: 46047 | B27: 46047 | F27: =SUM('TAMBOLAKA 2026'!$C27:$E27) -> 0
A28: 46048 | B28: 46048 | C28: =50000+51000+78000 -> 179000 | D28: =7697500+68000+300000+50000+450000 -> 8565500 | F28: =SUM('TAMBOLAKA 2026'!$C28:$E28) -> 8744500
A29: 46049 | B29: 46049 | F29: =SUM('TAMBOLAKA 2026'!$C29:$E29) -> 0
A30: 46050 | B30: 46050 | C30: =1447200+76000+26000 -> 1549200 | D30: =4545000 -> 4545000 | F30: =SUM('TAMBOLAKA 2026'!$C30:$E30) -> 6094200
A31: 46051 | B31: 46051 | C31: =26000+76000 -> 102000 | D31: =51000+34000+26000+13000 -> 124000 | F31: =SUM('TAMBOLAKA 2026'!$C31:$E31) -> 226000
A32: 46052 | B32: 46052 | C32: =51000 -> 51000 | D32: =3664500+26000+21000+150000 -> 3861500 | F32: =SUM('TAMBOLAKA 2026'!$C32:$E32) -> 3912500
A33: 46053 | B33: 46053 | C33: =20000+40000+52000+1497000+51000 -> 1660000 | D33: =300000+77000+450000 -> 827000 | F33: =SUM('TAMBOLAKA 2026'!$C33:$E33) -> 2487000
A34: 46054 | B34: 46054 | F34: =SUM('TAMBOLAKA 2026'!$C34:$E34) -> 0
A35: 46055 | B35: 46055 | C35: =76000+76000+981000+26000+51000+272000+77000+130000+26000 -> 1715000 | D35: =1255000+700000+100000+34000+52000+230000+77000 -> 2448000 | F35: =SUM('TAMBOLAKA 2026'!$C35:$E35) -> 4163000
A36: 46056 | B36: 46056 | C36: =100000+26000+26000+26000+159000 -> 337000 | F36: =SUM('TAMBOLAKA 2026'!$C36:$E36) -> 337000
A37: 46057 | B37: 46057 | D37: =7403000+50000+55000 -> 7508000 | F37: =SUM('TAMBOLAKA 2026'!$C37:$E37) -> 7508000
A38: 46058 | B38: 46058 | C38: =26000 -> 26000 | F38: =SUM('TAMBOLAKA 2026'!$C38:$E38) -> 26000
A39: 46059 | B39: 46059 | C39: =350000+26000 -> 376000 | D39: =301000+78000+2473500+250000+344000+200000 -> 3646500 | F39: =SUM('TAMBOLAKA 2026'!$C39:$E39) -> 4022500
A40: 46060 | B40: 46060 | C40: =1500000+550000+52000+26000+76000+102000+242000+26000+55000+211000 -> 2840000 | D40: =26000+34000+500000+400000 -> 960000 | F40: =SUM('TAMBOLAKA 2026'!$C40:$E40) -> 3800000
...

Sheet WAIBAKUL 2026
A1: TOTAL | C1: SETORAN BANK | F1: =SUBTOTAL(9,F3:F393) -> 65872759
A2: Hari | B2: Tanggal | C2: BRI | D2: BNI | E2: LAINNYA | F2: TOTAL SETORAN
A3: 46023 | B3: 46023 | F3: =SUM('WAIBAKUL 2026'!$C3:$E3) -> 0
A4: 46024 | B4: 46024 | F4: =SUM('WAIBAKUL 2026'!$C4:$E4) -> 0
A5: 46025 | B5: 46025 | F5: =SUM('WAIBAKUL 2026'!$C5:$E5) -> 0
A6: 46026 | B6: 46026 | F6: =SUM('WAIBAKUL 2026'!$C6:$E6) -> 0
A7: 46027 | B7: 46027 | F7: =SUM('WAIBAKUL 2026'!$C7:$E7) -> 0
A8: 46028 | B8: 46028 | C8: =5670197 -> 5670197 | F8: =SUM('WAIBAKUL 2026'!$C8:$E8) -> 5670197
A9: 46029 | B9: 46029 | F9: =SUM('WAIBAKUL 2026'!$C9:$E9) -> 0
A10: 46030 | B10: 46030 | F10: =SUM('WAIBAKUL 2026'!$C10:$E10) -> 0
A11: 46031 | B11: 46031 | F11: =SUM('WAIBAKUL 2026'!$C11:$E11) -> 0
A12: 46032 | B12: 46032 | F12: =SUM('WAIBAKUL 2026'!$C12:$E12) -> 0
A13: 46033 | B13: 46033 | F13: =SUM('WAIBAKUL 2026'!$C13:$E13) -> 0
A14: 46034 | B14: 46034 | C14: =7738299 -> 7738299 | F14: =SUM('WAIBAKUL 2026'!$C14:$E14) -> 7738299
A15: 46035 | B15: 46035 | F15: =SUM('WAIBAKUL 2026'!$C15:$E15) -> 0
A16: 46036 | B16: 46036 | F16: =SUM('WAIBAKUL 2026'!$C16:$E16) -> 0
A17: 46037 | B17: 46037 | C17: =3583025 -> 3583025 | F17: =SUM('WAIBAKUL 2026'!$C17:$E17) -> 3583025
A18: 46038 | B18: 46038 | F18: =SUM('WAIBAKUL 2026'!$C18:$E18) -> 0
A19: 46039 | B19: 46039 | F19: =SUM('WAIBAKUL 2026'!$C19:$E19) -> 0
A20: 46040 | B20: 46040 | F20: =SUM('WAIBAKUL 2026'!$C20:$E20) -> 0
A21: 46041 | B21: 46041 | F21: =SUM('WAIBAKUL 2026'!$C21:$E21) -> 0
A22: 46042 | B22: 46042 | C22: =8543255 -> 8543255 | F22: =SUM('WAIBAKUL 2026'!$C22:$E22) -> 8543255
A23: 46043 | B23: 46043 | F23: =SUM('WAIBAKUL 2026'!$C23:$E23) -> 0
A24: 46044 | B24: 46044 | F24: =SUM('WAIBAKUL 2026'!$C24:$E24) -> 0
A25: 46045 | B25: 46045 | F25: =SUM('WAIBAKUL 2026'!$C25:$E25) -> 0
A26: 46046 | B26: 46046 | F26: =SUM('WAIBAKUL 2026'!$C26:$E26) -> 0
A27: 46047 | B27: 46047 | F27: =SUM('WAIBAKUL 2026'!$C27:$E27) -> 0
A28: 46048 | B28: 46048 | F28: =SUM('WAIBAKUL 2026'!$C28:$E28) -> 0
A29: 46049 | B29: 46049 | C29: =7677000 -> 7677000 | F29: =SUM('WAIBAKUL 2026'!$C29:$E29) -> 7677000
A30: 46050 | B30: 46050 | F30: =SUM('WAIBAKUL 2026'!$C30:$E30) -> 0
A31: 46051 | B31: 46051 | F31: =SUM('WAIBAKUL 2026'!$C31:$E31) -> 0
A32: 46052 | B32: 46052 | F32: =SUM('WAIBAKUL 2026'!$C32:$E32) -> 0
A33: 46053 | B33: 46053 | F33: =SUM('WAIBAKUL 2026'!$C33:$E33) -> 0
A34: 46054 | B34: 46054 | F34: =SUM('WAIBAKUL 2026'!$C34:$E34) -> 0
A35: 46055 | B35: 46055 | F35: =SUM('WAIBAKUL 2026'!$C35:$E35) -> 0
A36: 46056 | B36: 46056 | C36: =6974500 -> 6974500 | F36: =SUM('WAIBAKUL 2026'!$C36:$E36) -> 6974500
A37: 46057 | B37: 46057 | F37: =SUM('WAIBAKUL 2026'!$C37:$E37) -> 0
A38: 46058 | B38: 46058 | F38: =SUM('WAIBAKUL 2026'!$C38:$E38) -> 0
A39: 46059 | B39: 46059 | C39: =3406743 -> 3406743 | F39: =SUM('WAIBAKUL 2026'!$C39:$E39) -> 3406743
A40: 46060 | B40: 46060 | F40: =SUM('WAIBAKUL 2026'!$C40:$E40) -> 0
...

Sheet WAIKABUBAK 2026
A1: TOTAL | C1: SETORAN BANK | F1: =SUBTOTAL(9,F3:F392) -> 123112096
A2: Hari | B2: Tanggal | C2: BRI | D2: BNI | E2: LAINNYA | F2: TOTAL SETORAN
A3: 46023 | B3: 46023 | F3: =SUM('WAIKABUBAK 2026'!$C3:$E3) -> 0
A4: 46024 | B4: 46024 | F4: =SUM('WAIKABUBAK 2026'!$C4:$E4) -> 0
A5: 46025 | B5: 46025 | C5: =66708 -> 66708 | D5: =1060000 -> 1060000 | F5: =SUM('WAIKABUBAK 2026'!$C5:$E5) -> 1126708
A6: 46026 | B6: 46026 | F6: =SUM('WAIKABUBAK 2026'!$C6:$E6) -> 0
A7: 46027 | B7: 46027 | C7: =231000+2802000 -> 3033000 | D7: =51000+471170 -> 522170 | F7: =SUM('WAIKABUBAK 2026'!$C7:$E7) -> 3555170
A8: 46028 | B8: 46028 | C8: =1832000 -> 1832000 | D8: =53350 -> 53350 | F8: =SUM('WAIKABUBAK 2026'!$C8:$E8) -> 1885350
A9: 46029 | B9: 46029 | C9: =1401023 -> 1401023 | F9: =SUM('WAIKABUBAK 2026'!$C9:$E9) -> 1401023
A10: 46030 | B10: 46030 | C10: =1250000 -> 1250000 | D10: =25200 -> 25200 | F10: =SUM('WAIKABUBAK 2026'!$C10:$E10) -> 1275200
A11: 46031 | B11: 46031 | C11: =2160000 -> 2160000 | D11: =179400+533000 -> 712400 | F11: =SUM('WAIKABUBAK 2026'!$C11:$E11) -> 2872400
A12: 46032 | B12: 46032 | F12: =SUM('WAIKABUBAK 2026'!$C12:$E12) -> 0
A13: 46033 | B13: 46033 | F13: =SUM('WAIKABUBAK 2026'!$C13:$E13) -> 0
A14: 46034 | B14: 46034 | C14: =6352000 -> 6352000 | D14: =481450 -> 481450 | F14: =SUM('WAIKABUBAK 2026'!$C14:$E14) -> 6833450
A15: 46035 | B15: 46035 | C15: =2647000+50000 -> 2697000 | D15: =524900 -> 524900 | F15: =SUM('WAIKABUBAK 2026'!$C15:$E15) -> 3221900
A16: 46036 | B16: 46036 | D16: =68000+145000+26000 -> 239000 | F16: =SUM('WAIKABUBAK 2026'!$C16:$E16) -> 239000
A17: 46037 | B17: 46037 | C17: =647000 -> 647000 | F17: =SUM('WAIKABUBAK 2026'!$C17:$E17) -> 647000
A18: 46038 | B18: 46038 | C18: =2513000 -> 2513000 | D18: =760580 -> 760580 | F18: =SUM('WAIKABUBAK 2026'!$C18:$E18) -> 3273580
A19: 46039 | B19: 46039 | D19: =494000+181000 -> 675000 | F19: =SUM('WAIKABUBAK 2026'!$C19:$E19) -> 675000
A20: 46040 | B20: 46040 | F20: =SUM('WAIKABUBAK 2026'!$C20:$E20) -> 0
A21: 46041 | B21: 46041 | C21: =3710820+13640 -> 3724460 | F21: =SUM('WAIKABUBAK 2026'!$C21:$E21) -> 3724460
A22: 46042 | B22: 46042 | D22: =1276000 -> 1276000 | F22: =SUM('WAIKABUBAK 2026'!$C22:$E22) -> 1276000
A23: 46043 | B23: 46043 | C23: =2219000+2376000 -> 4595000 | D23: =105700 -> 105700 | F23: =SUM('WAIKABUBAK 2026'!$C23:$E23) -> 4700700
A24: 46044 | B24: 46044 | C24: 1695300 | D24: =628000 -> 628000 | F24: =SUM('WAIKABUBAK 2026'!$C24:$E24) -> 2323300
A25: 46045 | B25: 46045 | C25: =3833250 -> 3833250 | D25: =953000 -> 953000 | F25: =SUM('WAIKABUBAK 2026'!$C25:$E25) -> 4786250
A26: 46046 | B26: 46046 | F26: =SUM('WAIKABUBAK 2026'!$C26:$E26) -> 0
A27: 46047 | B27: 46047 | D27: =108000 -> 108000 | F27: =SUM('WAIKABUBAK 2026'!$C27:$E27) -> 108000
A28: 46048 | B28: 46048 | C28: =7764860 -> 7764860 | F28: =SUM('WAIKABUBAK 2026'!$C28:$E28) -> 7764860
A29: 46049 | B29: 46049 | C29: =2601000 -> 2601000 | D29: =737000+224000 -> 961000 | F29: =SUM('WAIKABUBAK 2026'!$C29:$E29) -> 3562000
A30: 46050 | B30: 46050 | C30: =762000 -> 762000 | D30: =51150 -> 51150 | F30: =SUM('WAIKABUBAK 2026'!$C30:$E30) -> 813150
A31: 46051 | B31: 46051 | C31: =309438 -> 309438 | D31: =26000+427000 -> 453000 | F31: =SUM('WAIKABUBAK 2026'!$C31:$E31) -> 762438
A32: 46052 | B32: 46052 | C32: =2673140 -> 2673140 | F32: =SUM('WAIKABUBAK 2026'!$C32:$E32) -> 2673140
A33: 46053 | B33: 46053 | D33: =1015000+50000 -> 1065000 | F33: =SUM('WAIKABUBAK 2026'!$C33:$E33) -> 1065000
A34: 46054 | B34: 46054 | F34: =SUM('WAIKABUBAK 2026'!$C34:$E34) -> 0
A35: 46055 | B35: 46055 | C35: =1864000 -> 1864000 | F35: =SUM('WAIKABUBAK 2026'!$C35:$E35) -> 1864000
A36: 46056 | B36: 46056 | C36: =673660 -> 673660 | D36: =368200+1739000 -> 2107200 | F36: =SUM('WAIKABUBAK 2026'!$C36:$E36) -> 2780860
A37: 46057 | B37: 46057 | C37: =3535440 -> 3535440 | D37: =62000 -> 62000 | F37: =SUM('WAIKABUBAK 2026'!$C37:$E37) -> 3597440
A38: 46058 | B38: 46058 | C38: =1132000 -> 1132000 | D38: =126000 -> 126000 | F38: =SUM('WAIKABUBAK 2026'!$C38:$E38) -> 1258000
A39: 46059 | B39: 46059 | C39: =1506608 -> 1506608 | D39: =1012300+77000 -> 1089300 | F39: =SUM('WAIKABUBAK 2026'!$C39:$E39) -> 2595908
A40: 46060 | B40: 46060 | D40: =834000 -> 834000 | F40: =SUM('WAIKABUBAK 2026'!$C40:$E40) -> 834000
...

Sheet WAINGAPU 2026
A1: TOTAL | C1: SETORAN BANK | F1: =SUBTOTAL(9,F3:F398) -> 304505877
A2: Hari | B2: Tanggal | C2: BRI | D2: BNI | E2: LAINNYA | F2: TOTAL SETORAN
A3: 46023 | B3: 46023 | C3: =26000+52000+26000+34000+26000+51000+26000+176000+26000 -> 443000 | D3: =103000 -> 103000 | F3: =SUM('WAINGAPU 2026'!$C3:$E3) -> 546000
A4: 46024 | B4: 46024 | C4: =1641000+26000+236000 -> 1903000 | D4: =4680000+520000+242000+30000 -> 5472000 | F4: =SUM('WAINGAPU 2026'!$C4:$E4) -> 7375000
A5: 46025 | B5: 46025 | C5: =500000+31009+26000+34000+257000 -> 848009 | D5: =700000 -> 700000 | F5: =SUM('WAINGAPU 2026'!$C5:$E5) -> 1548009
A6: 46026 | B6: 46026 | D6: =51000 -> 51000 | F6: =SUM('WAINGAPU 2026'!$C6:$E6) -> 51000
A7: 46027 | B7: 46027 | C7: =195000+51000+392000+355000+257000 -> 1250000 | D7: =9072000+200000+4150000+156400+300000 -> 13878400 | F7: =SUM('WAINGAPU 2026'!$C7:$E7) -> 15128400
A8: 46028 | B8: 46028 | C8: =406500 -> 406500 | D8: =1000000+187000+100000 -> 1287000 | E8: =50000+50000 -> 100000 | F8: =SUM('WAINGAPU 2026'!$C8:$E8) -> 1793500
A9: 46029 | B9: 46029 | C9: =155950 -> 155950 | D9: =9906000+1000000+200000+259500+798000 -> 12163500 | F9: =SUM('WAINGAPU 2026'!$C9:$E9) -> 12319450
A10: 46030 | B10: 46030 | C10: =26000+51000+26000+288700+499999+51000+76000+102000+77000+101000 -> 1298699 | D10: =26000 -> 26000 | E10: =800000+100000+400000 -> 1300000 | F10: =SUM('WAINGAPU 2026'!$C10:$E10) -> 2624699
A11: 46031 | B11: 46031 | C11: =130000+51000 -> 181000 | D11: =9171000+51000+100000 -> 9322000 | E11: =60000 -> 60000 | F11: =SUM('WAINGAPU 2026'!$C11:$E11) -> 9563000
A12: 46032 | B12: 46032 | C12: =77000+393670+77000+243000+1890000+507015 -> 3187685 | D12: =140000+200000+500000 -> 840000 | F12: =SUM('WAINGAPU 2026'!$C12:$E12) -> 4027685
A13: 46033 | B13: 46033 | C13: =26000+26000+26000+221000+26000 -> 325000 | F13: =SUM('WAINGAPU 2026'!$C13:$E13) -> 325000
A14: 46034 | B14: 46034 | C14: =26000+26000+31000+51000+77000+77000+26000+138000+51000+26000+101000+102000 -> 732000 | D14: =11173000+100000 -> 11273000 | E14: =289000 -> 289000 | F14: =SUM('WAINGAPU 2026'!$C14:$E14) -> 12294000
A15: 46035 | B15: 46035 | C15: =97000+71000+101000+145000+350600 -> 764600 | D15: =500000 -> 500000 | F15: =SUM('WAINGAPU 2026'!$C15:$E15) -> 1264600
A16: 46036 | B16: 46036 | C16: =285000+26000+26000+26000 -> 363000 | D16: =9090000 -> 9090000 | F16: =SUM('WAINGAPU 2026'!$C16:$E16) -> 9453000
A17: 46037 | B17: 46037 | C17: =26000+96000+1000000+51000 -> 1173000 | D17: =3405000 -> 3405000 | F17: =SUM('WAINGAPU 2026'!$C17:$E17) -> 4578000
A18: 46038 | B18: 46038 | C18: =336000+26000+250000 -> 612000 | F18: =SUM('WAINGAPU 2026'!$C18:$E18) -> 612000
A19: 46039 | B19: 46039 | C19: =26000+26000+26000+51000+101000+26000+51000+97000+76000+26000+51000+26000+34000+31000+43000+51000 -> 742000 | D19: =76000+51000+100000+350000 -> 577000 | F19: =SUM('WAINGAPU 2026'!$C19:$E19) -> 1319000
A20: 46040 | B20: 46040 | C20: =291000 -> 291000 | F20: =SUM('WAINGAPU 2026'!$C20:$E20) -> 291000
A21: 46041 | B21: 46041 | C21: =51000+101000+201000+269000+51000+26000+270000+26000+26000+26000+26000+198000+100000+26000 -> 1397000 | D21: =10019000+500000+26000+125000+35000 -> 10705000 | F21: =SUM('WAINGAPU 2026'!$C21:$E21) -> 12102000
A22: 46042 | B22: 46042 | C22: =177000+26000+26000+49000+246000 -> 524000 | F22: =SUM('WAINGAPU 2026'!$C22:$E22) -> 524000
A23: 46043 | B23: 46043 | C23: =350000 -> 350000 | D23: =10184000+1000000 -> 11184000 | F23: =SUM('WAINGAPU 2026'!$C23:$E23) -> 11534000
A24: 46044 | B24: 46044 | C24: =26000+26000+26000+26000+26000+102000+26000+51000+349000+253000+26000+257000 -> 1194000 | D24: =135000+52000+26000 -> 213000 | F24: =SUM('WAINGAPU 2026'!$C24:$E24) -> 1407000
A25: 46045 | B25: 46045 | C25: =26000+26000+100000+229000+26000+26000+51000+300000+26000+50000+26000 -> 886000 | D25: =5330000+51000 -> 5381000 | F25: =SUM('WAINGAPU 2026'!$C25:$E25) -> 6267000
A26: 46046 | B26: 46046 | C26: =67000+26000+26000+51000+128000 -> 298000 | D26: =26000+26000 -> 52000 | F26: =SUM('WAINGAPU 2026'!$C26:$E26) -> 350000
A27: 46047 | B27: 46047 | C27: =26000+379000+26000 -> 431000 | D27: =300000 -> 300000 | F27: =SUM('WAINGAPU 2026'!$C27:$E27) -> 731000
A28: 46048 | B28: 46048 | C28: =26000+26000+26000+178000+51000+300000+999000+26000+26000+68000 -> 1726000 | D28: =10504000+1000000+100000 -> 11604000 | F28: =SUM('WAINGAPU 2026'!$C28:$E28) -> 13330000
A29: 46049 | B29: 46049 | C29: =89000 -> 89000 | D29: =45000 -> 45000 | E29: =48000 -> 48000 | F29: =SUM('WAINGAPU 2026'!$C29:$E29) -> 182000
A30: 46050 | B30: 46050 | C30: =253800+100000+631000 -> 984800 | D30: =13730000+200000 -> 13930000 | F30: =SUM('WAINGAPU 2026'!$C30:$E30) -> 14914800
A31: 46051 | B31: 46051 | C31: =26000+26000+201000+187000+26000+51000+26000+67000+750000+26000+26000+51000 -> 1463000 | F31: =SUM('WAINGAPU 2026'!$C31:$E31) -> 1463000
